Workbook

Sheet Исходная информация (2)
A1: Наименование оборудования | B1: Инвентарный номер | C1: Периодичность ТО | D1: График ТО | E1: Год сейчас | F1: Год следующий | G1: Инженер | H1: # | I1: Месяц следующее ТО | M1: Опции
A2: Генератор электрохирургический с универсальным набором комплектующих для монополярной и биполярной коагуляции | B2: 19987 | C2: 12 мес | D2: Июль | E2: 2026 | F2: 2027 | G2: Данилова К.И. | I2: Сентябрь | M2: Offset | N2: 8
A3: Комплект для проведения брахитерапии предстательной железы составе: Аппарат ультразвуковой Flex Focus 1202 c принадлежностями. Принадлежность к комплексу гамма-терапевтическому для брахиотерапии: Степпер, Принадлежность к комплексу гамма-терапевтическому для брахиотерапии: Держатель УЗИ датчика ВК, Принадлежность к комплексу гамма-терапевтическому для брахиотерапии: Кронштейн с противовесом для крепления степпера, Принадлежность к комплексу гамма-терапевтическому для брахиотерапии: Держатель шаблонов универсальный, Принадлежность к комплексу гамма-терапевтическому для брахиотерапии: Кейс для хранения кронштейна и степпера | B3: 20875 | C3: 12 мес | D3: Июль | E3: 2026 | F3: 2027 | G3: Данилова К.И. | I3: Октябрь
A4: Микроскоп операционный хирургический Leica PROvido | B4: 22970 | C4: 12 мес | D4: Июль | E4: 2026 | F4: 2027 | G4: Данилова К.И. | I4: Ноябрь
A5: Операционный стол универсальный (тип 1) | B5: 27137 | C5: 12 мес | D5: Июль | E5: 2026 | F5: 2027 | G5: Данилова К.И. | I5: Декабрь
A6: Операционный стол универсальный (тип 1) | B6: 27138 | C6: 12 мес | D6: Июль | E6: 2026 | F6: 2027 | G6: Данилова К.И. | I6: Январь
A7: Операционный стол универсальный (тип 1) | B7: 27139 | C7: 12 мес | D7: Июль | E7: 2026 | F7: 2027 | G7: Данилова К.И. | I7: Февраль
A8: Операционный стол универсальный (тип 1) | B8: 27140 | C8: 12 мес | D8: Июль | E8: 2026 | F8: 2027 | G8: Данилова К.И. | I8: Март
A9: Операционный стол универсальный (тип 1) | B9: 27141 | C9: 12 мес | D9: Июль | E9: 2026 | F9: 2027 | G9: Данилова К.И. | I9: Апрель
A10: Операционный стол универсальный (тип 1) | B10: 27142 | C10: 12 мес | D10: Июль | E10: 2026 | F10: 2027 | G10: Данилова К.И. | I10: Май
A11: Операционный стол универсальный (тип 1) | B11: 27143 | C11: 12 мес | D11: Июль | E11: 2026 | F11: 2027 | G11: Данилова К.И. | I11: Июнь
A12: Операционный стол универсальный (тип 1) | B12: 27144 | C12: 12 мес | D12: Июль | E12: 2026 | F12: 2027 | G12: Данилова К.И. | I12: Июль
A13: Операционный стол универсальный (тип 1) | B13: 27145 | C13: 12 мес | D13: Июль | E13: 2026 | F13: 2027 | G13: Данилова К.И. | I13: Август
A14: Операционный стол универсальный (тип 2) | B14: 27136 | C14: 12 мес | D14: Июль | E14: 2026 | F14: 2027 | G14: Данилова К.И. | I14: Сентябрь
... A47: Система автоматизированного планирования, управления и контроля результатов хирургического лечения | B47: 20231 | C47: 12 мес | D47: Июль | E47: 2026 | F47: 2027 | G47: Данилова К.И. | I47: Июнь

Sheet Исходная информация
A1: Наименование оборудования | B1: Инвентарный номер | C1: Периодичность ТО | D1: График ТО | E1: Год сейчас | F1: Год следующий | G1: Инженер | H1: # | I1: Месяц следующее ТО | M1: Опции
A2: Облучатель-рециркулятор воздуха ультрафиолетовый бактерицидный настенный ОРУБн-3-5-«КРОНТ» (Дезар-5) | B2: 21647 | C2: 12 мес | D2: Июль | E2: 2026 | F2: 2027 | G2: Данилова К.И. | I2: Сентябрь | M2: Offset | N2: 8
A3: Облучатель-рециркулятор воздуха ультрафиолетовый бактерицидный настенный ОРУБн-3-5-«КРОНТ» (Дезар-5) | B3: 21648 | C3: 12 мес | D3: Июль | E3: 2026 | F3: 2027 | G3: Данилова К.И. | I3: Октябрь
A4: Облучатель-рециркулятор воздуха ультрафиолетовый бактерицидный настенный ОРУБн-3-5-«КРОНТ» (Дезар-5) | B4: 21649 | C4: 12 мес | D4: Июль | E4: 2026 | F4: 2027 | G4: Данилова К.И. | I4: Ноябрь
A5: Стол операционный с принадлежностями HY Base 3000. "Нанджин Миндрей Био-Медикал Электроникс Ко., Лтд." | B5: 16917 | C5: 12 мес | D5: Июль | E5: 2026 | F5: 2027 | G5: Данилова К.И. | I5: Декабрь
A6: Стол операционный с принадлежностями HY Base 3000. "Нанджин Миндрей Био-Медикал Электроникс Ко., Лтд." | B6: 16918 | C6: 12 мес | D6: Июль | E6: 2026 | F6: 2027 | G6: Данилова К.И. | I6: Январь
A7: Устройство для запаивания пакетов (390 Вт) | B7: 27823 | C7: 12 мес | D7: Июль | E7: 2026 | F7: 2027 | G7: Данилова К.И. | I7: Февраль
A8: аппарат высокочастотный электрохирургический | B8: 000410124.04.80191719 | C8: 12 мес | D8: Июль | E8: 2026 | F8: 2027 | G8: Данилова К.И. | I8: Март
A9: видеоэндоскопический комплект HAMOU ENDOMAT | B9: 000410124.04.80191741 | C9: 12 мес | D9: Июль | E9: 2026 | F9: 2027 | G9: Данилова К.И. | I9: Апрель
A10: комплекс видеоэндоскопический HD | B10: 000410124.04.80191720 | C10: 12 мес | D10: Июль | E10: 2026 | F10: 2027 | G10: Данилова К.И. | I10: Май
A11: комплекс видеоэндоскопический Endomat | B11: 000410124.04.80191791 | C11: 12 мес | D11: Июль | E11: 2026 | F11: 2027 | G11: Данилова К.И. | I11: Июнь
A12: лупа хирургическая модель с расширенным полем в комплекте с осветителем | B12: 000410124.04.80191300 | C12: 12 мес | D12: Июль | E12: 2026 | F12: 2027 | G12: Данилова К.И. | I12: Июль
A13: отсасыватель универсальный с автоматическим поддержанием заданного уровня В-80А | B13: 000410124.04.80191910 | C13: 12 мес | D13: Июль | E13: 2026 | F13: 2027 | G13: Данилова К.И. | I13: Август
A14: отсасыватель универсальный с автоматическим поддержанием заданного уровня В-80А | B14: 000410124.04.80191912 | C14: 12 мес | D14: Июль | E14: 2026 | F14: 2027 | G14: Данилова К.И. | I14: Сентябрь
A15: отсасыватель универсальный с автоматическим поддержанием заданного уровня В-80А | B15: 000410124.04.80191916 | C15: 12 мес | D15: Июль | E15: 2026 | F15: 2027 | G15: Данилова К.И. | I15: Октябрь
A16: отсасыватель универсальный с автоматическим поддержанием заданного уровня В-80А | B16: 000410124.04.80191917 | C16: 12 мес | D16: Июль | E16: 2026 | F16: 2027 | G16: Данилова К.И. | I16: Ноябрь
A17: отсасыватель универсальный с автоматическим поддержанием заданного уровня В-80А | B17: 000410124.04.80191920 | C17: 12 мес | D17: Июль | E17: 2026 | F17: 2027 | G17: Данилова К.И. | I17: Декабрь
A18: отсасыватель универсальный с автоматическим поддержанием заданного уровня В-80А | B18: 000410124.04.80191924 | C18: 12 мес | D18: Июль | E18: 2026 | F18: 2027 | G18: Данилова К.И. | I18: Январь
A19: система архивации данных для эндоскопических стоек AIDA | B19: 000410124.04.80191649 | C19: 12 мес | D19: Июль | E19: 2026 | F19: 2027 | G19: Данилова К.И. | I19: Февраль
A20: система архивации данных для эндоскопических стоек AIDA | B20: 000410124.04.80191950 | C20: 12 мес | D20: Июль | E20: 2026 | F20: 2027 | G20: Данилова К.И. | I20: Март
A21: Лупа офтальмологическая бинокулярная HR2,5х/340 HEINE | B21: 13977 | C21: 12 мес | D21: Июль | E21: 2026 | F21: 2027 | G21: Данилова К.И. | I21: Апрель
A22: Лупа офтальмологическая бинокулярная HR2,5х/420 HEINE | B22: 13976 | C22: 12 мес | D22: Июль | E22: 2026 | F22: 2027 | G22: Данилова К.И. | I22: Май
A23: Устройство для обеспечения нейрохирургического доступа и позиционирования инструментов ViewSite Brain Access System | B23: 16562 | C23: 12 мес | D23: Июль | E23: 2026 | F23: 2027 | G23: Данилова К.И. | I23: Июнь
A24: GEN11, Генератор электрохирургический, ультразвуковой G11 | B24: 23016 | C24: 12 мес | D24: Июль | E24: 2026 | F24: 2027 | G24: Данилова К.И. | I24: Июль
A25: Аппарат электрохирургический моно- и биполярный Force FX | B25: 18521 | C25: 12 мес | D25: Июль | E25: 2026 | F25: 2027 | G25: Данилова К.И. | I25: Август
A26: Аппарат электрохирургический моно- и биполярный Force FX | B26: 18522 | C26: 12 мес | D26: Июль | E26: 2026 | F26: 2027 | G26: Данилова К.И. | I26: Сентябрь
A27: Аппарат электрохирургический моно- и биполярный Force FX | B27: 19009 | C27: 12 мес | D27: Июль | E27: 2026 | F27: 2027 | G27: Данилова К.И. | I27: Октябрь
A28: Аппарат электрохирургический моно- и биполярный Force FX | B28: 19010 | C28: 12 мес | D28: Июль | E28: 2026 | F28: 2027 | G28: Данилова К.И. | I28: Ноябрь
A29: блок управления со встроенным ирригационным устройством | B29: 001210124.01.1 | C29: 12 мес | D29: Июль | E29: 2026 | F29: 2027 | G29: Данилова К.И. | I29: Декабрь
A30: Генератор элекрохирургический ультразвуковой CSUS 6000 | B30: 25599 | C30: 12 мес | D30: Июль | E30: 2026 | F30: 2027 | G30: Данилова К.И. | I30: Январь
A31: Генератор электролигирующий Valleylab LS | B31: 18520 | D31: Июль | E31: 2026 | F31: 2027 | G31: Данилова К.И. | I31: Февраль
A32: Генератор электролигирующий Valleylab LS | B32: 19011 | C32: 12 мес | D32: Июль | E32: 2026 | F32: 2027 | G32: Данилова К.И. | I32: Март
A33: Генератор электролигирующий Valleylab LS | B33: 19012 | C33: 12 мес | D33: Июль | E33: 2026 | F33: 2027 | G33: Данилова К.И. | I33: Апрель
A34: Генератор электрохирургический, ультразвуковой G11 с принадлежностями (GEN 11) | B34: 20331 | C34: 12 мес | D34: Июль | E34: 2026 | F34: 2027 | G34: Данилова К.И. | I34: Май
A35: Генератор электрохирургический, ультразвуковой G11 с принадлежностями (GEN 11) | B35: 20332 | C35: 12 мес | D35: Июль | E35: 2026 | F35: 2027 | G35: Данилова К.И. | I35: Июнь
A36: Платформа энергетическая FT10 Valleylab | B36: 18523 | C36: 12 мес | D36: Июль | E36: 2026 | F36: 2027 | G36: Данилова К.И. | I36: Июль
A37: аппарат для челюстно-лицевой хирургии и имплантологии | B37: 001410124.04.6570 | C37: 12 мес | D37: Июль | E37: 2026 | F37: 2027 | G37: Данилова К.И. | I37: Август
A38: аппарат для электрохирургии (диатермкоагуляции) Force EZ | B38: 001410124.04.80191579 | C38: 12 мес | D38: Июль | E38: 2026 | F38: 2027 | G38: Данилова К.И. | I38: Сентябрь
A39: аппарат для электрохирургии (диатермкоагуляции) Force EZ | B39: 001410124.04.80191584 | C39: 12 мес | D39: Июль | E39: 2026 | F39: 2027 | G39: Данилова К.И. | I39: Октябрь
A40: датчик конвексный | B40: 001410124.04.2633 | C40: 12 мес | D40: Июль | E40: 2026 | F40: 2027 | G40: Данилова К.И. | I40: Ноябрь
...

Sheet Первые 24
A1: ="Наименование: " & INDIRECT(ADDRESS(INT(ROUNDUP(((ROW())/6), 1)) + 2, 1, 1, 1, "Исходная информация")) -> Наименование: Облучатель-рециркулятор воздуха ультрафиолетовый бактерицидный настенный ОРУБн-3-5-«КРОНТ» (Дезар-5) | C1: ="Наименование: " & INDIRECT(ADDRESS(INT(ROUNDUP(((ROW())/6), 1)) + (2+'Исходная информация'!$N$2), 1, 1, 1, "Исходная информация")) -> Наименование: комплекс видеоэндоскопический HD | E1: ="Наименование: " & INDIRECT(ADDRESS(INT(ROUNDUP(((ROW())/6), 1)) + (2+'Исходная информация'!$N$3), 1, 1, 1, "Исходная информация")) -> Наименование: Облучатель-рециркулятор воздуха ультрафиолетовый бактерицидный настенный ОРУБн-3-5-«КРОНТ» (Дезар-5)
A2: ="Инв. №: " & INDIRECT(ADDRESS(INT(ROUNDUP(((ROW())/6), 1)) + 2, 2, 1, 1, "Исходная информация")) -> Инв. №: 21647 | C2: ="Инв. №: " & INDIRECT(ADDRESS(INT(ROUNDUP(((ROW())/6), 1)) + (2+'Исходная информация'!$N$2), 2, 1, 1, "Исходная информация")) -> Инв. №: 000410124.04.80191720 | E2: ="Инв. №: " & INDIRECT(ADDRESS(INT(ROUNDUP(((ROW())/6), 1)) + (2+'Исходная информация'!$N$3), 2, 1, 1, "Исходная информация")) -> Инв. №: 21647
A3: ="Периодичность ТО: " & INDIRECT(ADDRESS(INT(ROUNDUP(((ROW())/6), 1)) + 2, 3, 1, 1, "Исходная информация")) -> Периодичность ТО: 12 мес | C3: ="Периодичность ТО: " & INDIRECT(ADDRESS(INT(ROUNDUP(((ROW())/6), 1)) + (2+'Исходная информация'!$N$2), 3, 1, 1, "Исходная информация")) -> Периодичность ТО: 12 мес | E3: ="Периодичность ТО: " & INDIRECT(ADDRESS(INT(ROUNDUP(((ROW())/6), 1)) + (2+'Исходная информация'!$N$3), 3, 1, 1, "Исходная информация")) -> Периодичность ТО: 12 мес
A4: ="Проведено ТО: " & INDIRECT(ADDRESS(INT(ROUNDUP(((ROW())/6), 1)) + 2, 4, 1, 1, "Исходная информация")) & " " & INDIRECT(ADDRESS(INT(ROUNDUP(((ROW())/6), 1)) + 2, 5, 1, 1, "Исходная информация")) & " г." -> Проведено ТО: Июль 2026 г. | C4: ="Проведено ТО: " & INDIRECT(ADDRESS(INT(ROUNDUP(((ROW())/6), 1)) + (2+'Исходная информация'!$N$2), 4, 1, 1, "Исходная информация")) & " " & INDIRECT(ADDRESS(INT(ROUNDUP(((ROW())/6), 1)) + (2+'Исходная информация'!$N$2), 5, 1, 1, "Исходная информация")) & " г." -> Проведено ТО: Июль 2026 г. | E4: ="Проведено ТО: " & INDIRECT(ADDRESS(INT(ROUNDUP(((ROW())/6), 1)) + (2+'Исходная информация'!$N$3), 4, 1, 1, "Исходная информация")) & " " & INDIRECT(ADDRESS(INT(ROUNDUP(((ROW())/6), 1)) + (2+'Исходная информация'!$N$3), 5, 1, 1, "Исходная информация")) & " г." -> Проведено ТО: Июль 2026 г.
A5: ="Следующее ТО: " & INDIRECT(ADDRESS(INT(ROUNDUP(((ROW())/6), 1)) + 2, 9, 1, 1, "Исходная информация")) & " " & INDIRECT(ADDRESS(INT(ROUNDUP(((ROW())/6), 1)) + 2, 6, 1, 1, "Исходная информация")) & " г." -> Следующее ТО: Сентябрь 2027 г. | C5: ="Следующее ТО: " & INDIRECT(ADDRESS(INT(ROUNDUP(((ROW())/6), 1)) + (2+'Исходная информация'!$N$2), 9, 1, 1, "Исходная информация")) & " " & INDIRECT(ADDRESS(INT(ROUNDUP(((ROW())/6), 1)) + (2+'Исходная информация'!$N$2), 6, 1, 1, "Исходная информация")) & " г." -> Следующее ТО: Май 2027 г. | E5: ="Следующее ТО: " & INDIRECT(ADDRESS(INT(ROUNDUP(((ROW())/6), 1)) + (2+'Исходная информация'!$N$3), 9, 1, 1, "Исходная информация")) & " " & INDIRECT(ADDRESS(INT(ROUNDUP(((ROW())/6), 1)) + (2+'Исходная информация'!$N$3), 6, 1, 1, "Исходная информация")) & " г." -> Следующее ТО: Сентябрь 2027 г.
A6: ="Инженер ОЭиРМО: " & INDIRECT(ADDRESS(INT(ROUNDUP(((ROW())/6), 1)) + 2, 7, 1, 1, "Исходная информация")) -> Инженер ОЭиРМО: Данилова К.И. | C6: ="Инженер ОЭиРМО: " & INDIRECT(ADDRESS(INT(ROUNDUP(((ROW())/6), 1)) + (2+'Исходная информация'!$N$2), 7, 1, 1, "Исходная информация")) -> Инженер ОЭиРМО: Данилова К.И. | E6: ="Инженер ОЭиРМО: " & INDIRECT(ADDRESS(INT(ROUNDUP(((ROW())/6), 1)) + (2+'Исходная информация'!$N$3), 7, 1, 1, "Исходная информация")) -> Инженер ОЭиРМО: Данилова К.И.
A7: ="Наименование: " & INDIRECT(ADDRESS(INT(ROUNDUP(((ROW())/6), 1)) + 2, 1, 1, 1, "Исходная информация")) -> Наименование: Облучатель-рециркулятор воздуха ультрафиолетовый бактерицидный настенный ОРУБн-3-5-«КРОНТ» (Дезар-5) | C7: ="Наименование: " & INDIRECT(ADDRESS(INT(ROUNDUP(((ROW())/6), 1)) + (2+'Исходная информация'!$N$2), 1, 1, 1, "Исходная информация")) -> Наименование: комплекс видеоэндоскопический Endomat | E7: ="Наименование: " & INDIRECT(ADDRESS(INT(ROUNDUP(((ROW())/6), 1)) + (2+'Исходная информация'!$N$3), 1, 1, 1, "Исходная информация")) -> Наименование: Облучатель-рециркулятор воздуха ультрафиолетовый бактерицидный настенный ОРУБн-3-5-«КРОНТ» (Дезар-5)
A8: ="Инв. №: " & INDIRECT(ADDRESS(INT(ROUNDUP(((ROW())/6), 1)) + 2, 2, 1, 1, "Исходная информация")) -> Инв. №: 21648 | C8: ="Инв. №: " & INDIRECT(ADDRESS(INT(ROUNDUP(((ROW())/6), 1)) + (2+'Исходная информация'!$N$2), 2, 1, 1, "Исходная информация")) -> Инв. №: 000410124.04.80191791 | E8: ="Инв. №: " & INDIRECT(ADDRESS(INT(ROUNDUP(((ROW())/6), 1)) + (2+'Исходная информация'!$N$3), 2, 1, 1, "Исходная информация")) -> Инв. №: 21648
A9: ="Периодичность ТО: " & INDIRECT(ADDRESS(INT(ROUNDUP(((ROW())/6), 1)) + 2, 3, 1, 1, "Исходная информация")) -> Периодичность ТО: 12 мес | C9: ="Периодичность ТО: " & INDIRECT(ADDRESS(INT(ROUNDUP(((ROW())/6), 1)) + (2+'Исходная информация'!$N$2), 3, 1, 1, "Исходная информация")) -> Периодичность ТО: 12 мес | E9: ="Периодичность ТО: " & INDIRECT(ADDRESS(INT(ROUNDUP(((ROW())/6), 1)) + (2+'Исходная информация'!$N$3), 3, 1, 1, "Исходная информация")) -> Периодичность ТО: 12 мес
A10: ="Проведено ТО: " & INDIRECT(ADDRESS(INT(ROUNDUP(((ROW())/6), 1)) + 2, 4, 1, 1, "Исходная информация")) & " " & INDIRECT(ADDRESS(INT(ROUNDUP(((ROW())/6), 1)) + 2, 5, 1, 1, "Исходная информация")) & " г." -> Проведено ТО: Июль 2026 г. | C10: ="Проведено ТО: " & INDIRECT(ADDRESS(INT(ROUNDUP(((ROW())/6), 1)) + (2+'Исходная информация'!$N$2), 4, 1, 1, "Исходная информация")) & " " & INDIRECT(ADDRESS(INT(ROUNDUP(((ROW())/6), 1)) + (2+'Исходная информация'!$N$2), 5, 1, 1, "Исходная информация")) & " г." -> Проведено ТО: Июль 2026 г. | E10: ="Проведено ТО: " & INDIRECT(ADDRESS(INT(ROUNDUP(((ROW())/6), 1)) + (2+'Исходная информация'!$N$3), 4, 1, 1, "Исходная информация")) & " " & INDIRECT(ADDRESS(INT(ROUNDUP(((ROW())/6), 1)) + (2+'Исходная информация'!$N$3), 5, 1, 1, "Исходная информация")) & " г." -> Проведено ТО: Июль 2026 г.
A11: ="Следующее ТО: " & INDIRECT(ADDRESS(INT(ROUNDUP(((ROW())/6), 1)) + 2, 9, 1, 1, "Исходная информация")) & " " & INDIRECT(ADDRESS(INT(ROUNDUP(((ROW())/6), 1)) + 2, 6, 1, 1, "Исходная информация")) & " г." -> Следующее ТО: Октябрь 2027 г. | C11: ="Следующее ТО: " & INDIRECT(ADDRESS(INT(ROUNDUP(((ROW())/6), 1)) + (2+'Исходная информация'!$N$2), 9, 1, 1, "Исходная информация")) & " " & INDIRECT(ADDRESS(INT(ROUNDUP(((ROW())/6), 1)) + (2+'Исходная информация'!$N$2), 6, 1, 1, "Исходная информация")) & " г." -> Следующее ТО: Июнь 2027 г. | E11: ="Следующее ТО: " & INDIRECT(ADDRESS(INT(ROUNDUP(((ROW())/6), 1)) + (2+'Исходная информация'!$N$3), 9, 1, 1, "Исходная информация")) & " " & INDIRECT(ADDRESS(INT(ROUNDUP(((ROW())/6), 1)) + (2+'Исходная информация'!$N$3), 6, 1, 1, "Исходная информация")) & " г." -> Следующее ТО: Октябрь 2027 г.
A12: ="Инженер ОЭиРМО: " & INDIRECT(ADDRESS(INT(ROUNDUP(((ROW())/6), 1)) + 2, 7, 1, 1, "Исходная информация")) -> Инженер ОЭиРМО: Данилова К.И. | C12: ="Инженер ОЭиРМО: " & INDIRECT(ADDRESS(INT(ROUNDUP(((ROW())/6), 1)) + (2+'Исходная информация'!$N$2), 7, 1, 1, "Исходная информация")) -> Инженер ОЭиРМО: Данилова К.И. | E12: ="Инженер ОЭиРМО: " & INDIRECT(ADDRESS(INT(ROUNDUP(((ROW())/6), 1)) + (2+'Исходная информация'!$N$3), 7, 1, 1, "Исходная информация")) -> Инженер ОЭиРМО: Данилова К.И.
A13: ="Наименование: " & INDIRECT(ADDRESS(INT(ROUNDUP(((ROW())/6), 1)) + 2, 1, 1, 1, "Исходная информация")) -> Наименование: Облучатель-рециркулятор воздуха ультрафиолетовый бактерицидный настенный ОРУБн-3-5-«КРОНТ» (Дезар-5) | C13: ="Наименование: " & INDIRECT(ADDRESS(INT(ROUNDUP(((ROW())/6), 1)) + (2+'Исходная информация'!$N$2), 1, 1, 1, "Исходная информация")) -> Наименование: лупа хирургическая модель с расширенным полем в комплекте с осветителем | E13: ="Наименование: " & INDIRECT(ADDRESS(INT(ROUNDUP(((ROW())/6), 1)) + (2+'Исходная информация'!$N$3), 1, 1, 1, "Исходная информация")) -> Наименование: Облучатель-рециркулятор воздуха ультрафиолетовый бактерицидный настенный ОРУБн-3-5-«КРОНТ» (Дезар-5)
A14: ="Инв. №: " & INDIRECT(ADDRESS(INT(ROUNDUP(((ROW())/6), 1)) + 2, 2, 1, 1, "Исходная информация")) -> Инв. №: 21649 | C14: ="Инв. №: " & INDIRECT(ADDRESS(INT(ROUNDUP(((ROW())/6), 1)) + (2+'Исходная информация'!$N$2), 2, 1, 1, "Исходная информация")) -> Инв. №: 000410124.04.80191300 | E14: ="Инв. №: " & INDIRECT(ADDRESS(INT(ROUNDUP(((ROW())/6), 1)) + (2+'Исходная информация'!$N$3), 2, 1, 1, "Исходная информация")) -> Инв. №: 21649
A15: ="Периодичность ТО: " & INDIRECT(ADDRESS(INT(ROUNDUP(((ROW())/6), 1)) + 2, 3, 1, 1, "Исходная информация")) -> Периодичность ТО: 12 мес | C15: ="Периодичность ТО: " & INDIRECT(ADDRESS(INT(ROUNDUP(((ROW())/6), 1)) + (2+'Исходная информация'!$N$2), 3, 1, 1, "Исходная информация")) -> Периодичность ТО: 12 мес | E15: ="Периодичность ТО: " & INDIRECT(ADDRESS(INT(ROUNDUP(((ROW())/6), 1)) + (2+'Исходная информация'!$N$3), 3, 1, 1, "Исходная информация")) -> Периодичность ТО: 12 мес
A16: ="Проведено ТО: " & INDIRECT(ADDRESS(INT(ROUNDUP(((ROW())/6), 1)) + 2, 4, 1, 1, "Исходная информация")) & " " & INDIRECT(ADDRESS(INT(ROUNDUP(((ROW())/6), 1)) + 2, 5, 1, 1, "Исходная информация")) & " г." -> Проведено ТО: Июль 2026 г. | C16: ="Проведено ТО: " & INDIRECT(ADDRESS(INT(ROUNDUP(((ROW())/6), 1)) + (2+'Исходная информация'!$N$2), 4, 1, 1, "Исходная информация")) & " " & INDIRECT(ADDRESS(INT(ROUNDUP(((ROW())/6), 1)) + (2+'Исходная информация'!$N$2), 5, 1, 1, "Исходная информация")) & " г." -> Проведено ТО: Июль 2026 г. | E16: ="Проведено ТО: " & INDIRECT(ADDRESS(INT(ROUNDUP(((ROW())/6), 1)) + (2+'Исходная информация'!$N$3), 4, 1, 1, "Исходная информация")) & " " & INDIRECT(ADDRESS(INT(ROUNDUP(((ROW())/6), 1)) + (2+'Исходная информация'!$N$3), 5, 1, 1, "Исходная информация")) & " г." -> Проведено ТО: Июль 2026 г.
A17: ="Следующее ТО: " & INDIRECT(ADDRESS(INT(ROUNDUP(((ROW())/6), 1)) + 2, 9, 1, 1, "Исходная информация")) & " " & INDIRECT(ADDRESS(INT(ROUNDUP(((ROW())/6), 1)) + 2, 6, 1, 1, "Исходная информация")) & " г." -> Следующее ТО: Ноябрь 2027 г. | C17: ="Следующее ТО: " & INDIRECT(ADDRESS(INT(ROUNDUP(((ROW())/6), 1)) + (2+'Исходная информация'!$N$2), 9, 1, 1, "Исходная информация")) & " " & INDIRECT(ADDRESS(INT(ROUNDUP(((ROW())/6), 1)) + (2+'Исходная информация'!$N$2), 6, 1, 1, "Исходная информация")) & " г." -> Следующее ТО: Июль 2027 г. | E17: ="Следующее ТО: " & INDIRECT(ADDRESS(INT(ROUNDUP(((ROW())/6), 1)) + (2+'Исходная информация'!$N$3), 9, 1, 1, "Исходная информация")) & " " & INDIRECT(ADDRESS(INT(ROUNDUP(((ROW())/6), 1)) + (2+'Исходная информация'!$N$3), 6, 1, 1, "Исходная информация")) & " г." -> Следующее ТО: Ноябрь 2027 г.
A18: ="Инженер ОЭиРМО: " & INDIRECT(ADDRESS(INT(ROUNDUP(((ROW())/6), 1)) + 2, 7, 1, 1, "Исходная информация")) -> Инженер ОЭиРМО: Данилова К.И. | C18: ="Инженер ОЭиРМО: " & INDIRECT(ADDRESS(INT(ROUNDUP(((ROW())/6), 1)) + (2+'Исходная информация'!$N$2), 7, 1, 1, "Исходная информация")) -> Инженер ОЭиРМО: Данилова К.И. | E18: ="Инженер ОЭиРМО: " & INDIRECT(ADDRESS(INT(ROUNDUP(((ROW())/6), 1)) + (2+'Исходная информация'!$N$3), 7, 1, 1, "Исходная информация")) -> Инженер ОЭиРМО: Данилова К.И.
A19: ="Наименование: " & INDIRECT(ADDRESS(INT(ROUNDUP(((ROW())/6), 1)) + 2, 1, 1, 1, "Исходная информация")) -> Наименование: Стол операционный с принадлежностями HY Base 3000. "Нанджин Миндрей Био-Медикал Электроникс Ко., Лтд." | C19: ="Наименование: " & INDIRECT(ADDRESS(INT(ROUNDUP(((ROW())/6), 1)) + (2+'Исходная информация'!$N$2), 1, 1, 1, "Исходная информация")) -> Наименование: отсасыватель универсальный с автоматическим поддержанием заданного уровня В-80А | E19: ="Наименование: " & INDIRECT(ADDRESS(INT(ROUNDUP(((ROW())/6), 1)) + (2+'Исходная информация'!$N$3), 1, 1, 1, "Исходная информация")) -> Наименование: Стол операционный с принадлежностями HY Base 3000. "Нанджин Миндрей Био-Медикал Электроникс Ко., Лтд."
A20: ="Инв. №: " & INDIRECT(ADDRESS(INT(ROUNDUP(((ROW())/6), 1)) + 2, 2, 1, 1, "Исходная информация")) -> Инв. №: 16917 | C20: ="Инв. №: " & INDIRECT(ADDRESS(INT(ROUNDUP(((ROW())/6), 1)) + (2+'Исходная информация'!$N$2), 2, 1, 1, "Исходная информация")) -> Инв. №: 000410124.04.80191910 | E20: ="Инв. №: " & INDIRECT(ADDRESS(INT(ROUNDUP(((ROW())/6), 1)) + (2+'Исходная информация'!$N$3), 2, 1, 1, "Исходная информация")) -> Инв. №: 16917
A21: ="Периодичность ТО: " & INDIRECT(ADDRESS(INT(ROUNDUP(((ROW())/6), 1)) + 2, 3, 1, 1, "Исходная информация")) -> Периодичность ТО: 12 мес | C21: ="Периодичность ТО: " & INDIRECT(ADDRESS(INT(ROUNDUP(((ROW())/6), 1)) + (2+'Исходная информация'!$N$2), 3, 1, 1, "Исходная информация")) -> Периодичность ТО: 12 мес | E21: ="Периодичность ТО: " & INDIRECT(ADDRESS(INT(ROUNDUP(((ROW())/6), 1)) + (2+'Исходная информация'!$N$3), 3, 1, 1, "Исходная информация")) -> Периодичность ТО: 12 мес
A22: ="Проведено ТО: " & INDIRECT(ADDRESS(INT(ROUNDUP(((ROW())/6), 1)) + 2, 4, 1, 1, "Исходная информация")) & " " & INDIRECT(ADDRESS(INT(ROUNDUP(((ROW())/6), 1)) + 2, 5, 1, 1, "Исходная информация")) & " г." -> Проведено ТО: Июль 2026 г. | C22: ="Проведено ТО: " & INDIRECT(ADDRESS(INT(ROUNDUP(((ROW())/6), 1)) + (2+'Исходная информация'!$N$2), 4, 1, 1, "Исходная информация")) & " " & INDIRECT(ADDRESS(INT(ROUNDUP(((ROW())/6), 1)) + (2+'Исходная информация'!$N$2), 5, 1, 1, "Исходная информация")) & " г." -> Проведено ТО: Июль 2026 г. | E22: ="Проведено ТО: " & INDIRECT(ADDRESS(INT(ROUNDUP(((ROW())/6), 1)) + (2+'Исходная информация'!$N$3), 4, 1, 1, "Исходная информация")) & " " & INDIRECT(ADDRESS(INT(ROUNDUP(((ROW())/6), 1)) + (2+'Исходная информация'!$N$3), 5, 1, 1, "Исходная информация")) & " г." -> Проведено ТО: Июль 2026 г.
A23: ="Следующее ТО: " & INDIRECT(ADDRESS(INT(ROUNDUP(((ROW())/6), 1)) + 2, 9, 1, 1, "Исходная информация")) & " " & INDIRECT(ADDRESS(INT(ROUNDUP(((ROW())/6), 1)) + 2, 6, 1, 1, "Исходная информация")) & " г." -> Следующее ТО: Декабрь 2027 г. | C23: ="Следующее ТО: " & INDIRECT(ADDRESS(INT(ROUNDUP(((ROW())/6), 1)) + (2+'Исходная информация'!$N$2), 9, 1, 1, "Исходная информация")) & " " & INDIRECT(ADDRESS(INT(ROUNDUP(((ROW())/6), 1)) + (2+'Исходная информация'!$N$2), 6, 1, 1, "Исходная информация")) & " г." -> Следующее ТО: Август 2027 г. | E23: ="Следующее ТО: " & INDIRECT(ADDRESS(INT(ROUNDUP(((ROW())/6), 1)) + (2+'Исходная информация'!$N$3), 9, 1, 1, "Исходная информация")) & " " & INDIRECT(ADDRESS(INT(ROUNDUP(((ROW())/6), 1)) + (2+'Исходная информация'!$N$3), 6, 1, 1, "Исходная информация")) & " г." -> Следующее ТО: Декабрь 2027 г.
A24: ="Инженер ОЭиРМО: " & INDIRECT(ADDRESS(INT(ROUNDUP(((ROW())/6), 1)) + 2, 7, 1, 1, "Исходная информация")) -> Инженер ОЭиРМО: Данилова К.И. | C24: ="Инженер ОЭиРМО: " & INDIRECT(ADDRESS(INT(ROUNDUP(((ROW())/6), 1)) + (2+'Исходная информация'!$N$2), 7, 1, 1, "Исходная информация")) -> Инженер ОЭиРМО: Данилова К.И. | E24: ="Инженер ОЭиРМО: " & INDIRECT(ADDRESS(INT(ROUNDUP(((ROW())/6), 1)) + (2+'Исходная информация'!$N$3), 7, 1, 1, "Исходная информация")) -> Инженер ОЭиРМО: Данилова К.И.
A25: ="Наименование: " & INDIRECT(ADDRESS(INT(ROUNDUP(((ROW())/6), 1)) + 2, 1, 1, 1, "Исходная информация")) -> Наименование: Стол операционный с принадлежностями HY Base 3000. "Нанджин Миндрей Био-Медикал Электроникс Ко., Лтд." | C25: ="Наименование: " & INDIRECT(ADDRESS(INT(ROUNDUP(((ROW())/6), 1)) + (2+'Исходная информация'!$N$2), 1, 1, 1, "Исходная информация")) -> Наименование: отсасыватель универсальный с автоматическим поддержанием заданного уровня В-80А | E25: ="Наименование: " & INDIRECT(ADDRESS(INT(ROUNDUP(((ROW())/6), 1)) + (2+'Исходная информация'!$N$3), 1, 1, 1, "Исходная информация")) -> Наименование: Стол операционный с принадлежностями HY Base 3000. "Нанджин Миндрей Био-Медикал Электроникс Ко., Лтд."
A26: ="Инв. №: " & INDIRECT(ADDRESS(INT(ROUNDUP(((ROW())/6), 1)) + 2, 2, 1, 1, "Исходная информация")) -> Инв. №: 16918 | C26: ="Инв. №: " & INDIRECT(ADDRESS(INT(ROUNDUP(((ROW())/6), 1)) + (2+'Исходная информация'!$N$2), 2, 1, 1, "Исходная информация")) -> Инв. №: 000410124.04.80191912 | E26: ="Инв. №: " & INDIRECT(ADDRESS(INT(ROUNDUP(((ROW())/6), 1)) + (2+'Исходная информация'!$N$3), 2, 1, 1, "Исходная информация")) -> Инв. №: 16918
A27: ="Периодичность ТО: " & INDIRECT(ADDRESS(INT(ROUNDUP(((ROW())/6), 1)) + 2, 3, 1, 1, "Исходная информация")) -> Периодичность ТО: 12 мес | C27: ="Периодичность ТО: " & INDIRECT(ADDRESS(INT(ROUNDUP(((ROW())/6), 1)) + (2+'Исходная информация'!$N$2), 3, 1, 1, "Исходная информация")) -> Периодичность ТО: 12 мес | E27: ="Периодичность ТО: " & INDIRECT(ADDRESS(INT(ROUNDUP(((ROW())/6), 1)) + (2+'Исходная информация'!$N$3), 3, 1, 1, "Исходная информация")) -> Периодичность ТО: 12 мес
A28: ="Проведено ТО: " & INDIRECT(ADDRESS(INT(ROUNDUP(((ROW())/6), 1)) + 2, 4, 1, 1, "Исходная информация")) & " " & INDIRECT(ADDRESS(INT(ROUNDUP(((ROW())/6), 1)) + 2, 5, 1, 1, "Исходная информация")) & " г." -> Проведено ТО: Июль 2026 г. | C28: ="Проведено ТО: " & INDIRECT(ADDRESS(INT(ROUNDUP(((ROW())/6), 1)) + (2+'Исходная информация'!$N$2), 4, 1, 1, "Исходная информация")) & " " & INDIRECT(ADDRESS(INT(ROUNDUP(((ROW())/6), 1)) + (2+'Исходная информация'!$N$2), 5, 1, 1, "Исходная информация")) & " г." -> Проведено ТО: Июль 2026 г. | E28: ="Проведено ТО: " & INDIRECT(ADDRESS(INT(ROUNDUP(((ROW())/6), 1)) + (2+'Исходная информация'!$N$3), 4, 1, 1, "Исходная информация")) & " " & INDIRECT(ADDRESS(INT(ROUNDUP(((ROW())/6), 1)) + (2+'Исходная информация'!$N$3), 5, 1, 1, "Исходная информация")) & " г." -> Проведено ТО: Июль 2026 г.
A29: ="Следующее ТО: " & INDIRECT(ADDRESS(INT(ROUNDUP(((ROW())/6), 1)) + 2, 9, 1, 1, "Исходная информация")) & " " & INDIRECT(ADDRESS(INT(ROUNDUP(((ROW())/6), 1)) + 2, 6, 1, 1, "Исходная информация")) & " г." -> Следующее ТО: Январь 2027 г. | C29: ="Следующее ТО: " & INDIRECT(ADDRESS(INT(ROUNDUP(((ROW())/6), 1)) + (2+'Исходная информация'!$N$2), 9, 1, 1, "Исходная информация")) & " " & INDIRECT(ADDRESS(INT(ROUNDUP(((ROW())/6), 1)) + (2+'Исходная информация'!$N$2), 6, 1, 1, "Исходная информация")) & " г." -> Следующее ТО: Сентябрь 2027 г. | E29: ="Следующее ТО: " & INDIRECT(ADDRESS(INT(ROUNDUP(((ROW())/6), 1)) + (2+'Исходная информация'!$N$3), 9, 1, 1, "Исходная информация")) & " " & INDIRECT(ADDRESS(INT(ROUNDUP(((ROW())/6), 1)) + (2+'Исходная информация'!$N$3), 6, 1, 1, "Исходная информация")) & " г." -> Следующее ТО: Январь 2027 г.
A30: ="Инженер ОЭиРМО: " & INDIRECT(ADDRESS(INT(ROUNDUP(((ROW())/6), 1)) + 2, 7, 1, 1, "Исходная информация")) -> Инженер ОЭиРМО: Данилова К.И. | C30: ="Инженер ОЭиРМО: " & INDIRECT(ADDRESS(INT(ROUNDUP(((ROW())/6), 1)) + (2+'Исходная информация'!$N$2), 7, 1, 1, "Исходная информация")) -> Инженер ОЭиРМО: Данилова К.И. | E30: ="Инженер ОЭиРМО: " & INDIRECT(ADDRESS(INT(ROUNDUP(((ROW())/6), 1)) + (2+'Исходная информация'!$N$3), 7, 1, 1, "Исходная информация")) -> Инженер ОЭиРМО: Данилова К.И.
A31: ="Наименование: " & INDIRECT(ADDRESS(INT(ROUNDUP(((ROW())/6), 1)) + 2, 1, 1, 1, "Исходная информация")) -> Наименование: Устройство для запаивания пакетов (390 Вт) | C31: ="Наименование: " & INDIRECT(ADDRESS(INT(ROUNDUP(((ROW())/6), 1)) + (2+'Исходная информация'!$N$2), 1, 1, 1, "Исходная информация")) -> Наименование: отсасыватель универсальный с автоматическим поддержанием заданного уровня В-80А | E31: ="Наименование: " & INDIRECT(ADDRESS(INT(ROUNDUP(((ROW())/6), 1)) + (2+'Исходная информация'!$N$3), 1, 1, 1, "Исходная информация")) -> Наименование: Устройство для запаивания пакетов (390 Вт)
A32: ="Инв. №: " & INDIRECT(ADDRESS(INT(ROUNDUP(((ROW())/6), 1)) + 2, 2, 1, 1, "Исходная информация")) -> Инв. №: 27823 | C32: ="Инв. №: " & INDIRECT(ADDRESS(INT(ROUNDUP(((ROW())/6), 1)) + (2+'Исходная информация'!$N$2), 2, 1, 1, "Исходная информация")) -> Инв. №: 000410124.04.80191916 | E32: ="Инв. №: " & INDIRECT(ADDRESS(INT(ROUNDUP(((ROW())/6), 1)) + (2+'Исходная информация'!$N$3), 2, 1, 1, "Исходная информация")) -> Инв. №: 27823
A33: ="Периодичность ТО: " & INDIRECT(ADDRESS(INT(ROUNDUP(((ROW())/6), 1)) + 2, 3, 1, 1, "Исходная информация")) -> Периодичность ТО: 12 мес | C33: ="Периодичность ТО: " & INDIRECT(ADDRESS(INT(ROUNDUP(((ROW())/6), 1)) + (2+'Исходная информация'!$N$2), 3, 1, 1, "Исходная информация")) -> Периодичность ТО: 12 мес | E33: ="Периодичность ТО: " & INDIRECT(ADDRESS(INT(ROUNDUP(((ROW())/6), 1)) + (2+'Исходная информация'!$N$3), 3, 1, 1, "Исходная информация")) -> Периодичность ТО: 12 мес
A34: ="Проведено ТО: " & INDIRECT(ADDRESS(INT(ROUNDUP(((ROW())/6), 1)) + 2, 4, 1, 1, "Исходная информация")) & " " & INDIRECT(ADDRESS(INT(ROUNDUP(((ROW())/6), 1)) + 2, 5, 1, 1, "Исходная информация")) & " г." -> Проведено ТО: Июль 2026 г. | C34: ="Проведено ТО: " & INDIRECT(ADDRESS(INT(ROUNDUP(((ROW())/6), 1)) + (2+'Исходная информация'!$N$2), 4, 1, 1, "Исходная информация")) & " " & INDIRECT(ADDRESS(INT(ROUNDUP(((ROW())/6), 1)) + (2+'Исходная информация'!$N$2), 5, 1, 1, "Исходная информация")) & " г." -> Проведено ТО: Июль 2026 г. | E34: ="Проведено ТО: " & INDIRECT(ADDRESS(INT(ROUNDUP(((ROW())/6), 1)) + (2+'Исходная информация'!$N$3), 4, 1, 1, "Исходная информация")) & " " & INDIRECT(ADDRESS(INT(ROUNDUP(((ROW())/6), 1)) + (2+'Исходная информация'!$N$3), 5, 1, 1, "Исходная информация")) & " г." -> Проведено ТО: Июль 2026 г.
A35: ="Следующее ТО: " & INDIRECT(ADDRESS(INT(ROUNDUP(((ROW())/6), 1)) + 2, 9, 1, 1, "Исходная информация")) & " " & INDIRECT(ADDRESS(INT(ROUNDUP(((ROW())/6), 1)) + 2, 6, 1, 1, "Исходная информация")) & " г." -> Следующее ТО: Февраль 2027 г. | C35: ="Следующее ТО: " & INDIRECT(ADDRESS(INT(ROUNDUP(((ROW())/6), 1)) + (2+'Исходная информация'!$N$2), 9, 1, 1, "Исходная информация")) & " " & INDIRECT(ADDRESS(INT(ROUNDUP(((ROW())/6), 1)) + (2+'Исходная информация'!$N$2), 6, 1, 1, "Исходная информация")) & " г." -> Следующее ТО: Октябрь 2027 г. | E35: ="Следующее ТО: " & INDIRECT(ADDRESS(INT(ROUNDUP(((ROW())/6), 1)) + (2+'Исходная информация'!$N$3), 9, 1, 1, "Исходная информация")) & " " & INDIRECT(ADDRESS(INT(ROUNDUP(((ROW())/6), 1)) + (2+'Исходная информация'!$N$3), 6, 1, 1, "Исходная информация")) & " г." -> Следующее ТО: Февраль 2027 г.
A36: ="Инженер ОЭиРМО: " & INDIRECT(ADDRESS(INT(ROUNDUP(((ROW())/6), 1)) + 2, 7, 1, 1, "Исходная информация")) -> Инженер ОЭиРМО: Данилова К.И. | C36: ="Инженер ОЭиРМО: " & INDIRECT(ADDRESS(INT(ROUNDUP(((ROW())/6), 1)) + (2+'Исходная информация'!$N$2), 7, 1, 1, "Исходная информация")) -> Инженер ОЭиРМО: Данилова К.И. | E36: ="Инженер ОЭиРМО: " & INDIRECT(ADDRESS(INT(ROUNDUP(((ROW())/6), 1)) + (2+'Исходная информация'!$N$3), 7, 1, 1, "Исходная информация")) -> Инженер ОЭиРМО: Данилова К.И.
A37: ="Наименование: " & INDIRECT(ADDRESS(INT(ROUNDUP(((ROW())/6), 1)) + 2, 1, 1, 1, "Исходная информация")) -> Наименование: аппарат высокочастотный электрохирургический | C37: ="Наименование: " & INDIRECT(ADDRESS(INT(ROUNDUP(((ROW())/6), 1)) + (2+'Исходная информация'!$N$2), 1, 1, 1, "Исходная информация")) -> Наименование: отсасыватель универсальный с автоматическим поддержанием заданного уровня В-80А | E37: ="Наименование: " & INDIRECT(ADDRESS(INT(ROUNDUP(((ROW())/6), 1)) + (2+'Исходная информация'!$N$3), 1, 1, 1, "Исходная информация")) -> Наименование: аппарат высокочастотный электрохирургический
A38: ="Инв. №: " & INDIRECT(ADDRESS(INT(ROUNDUP(((ROW())/6), 1)) + 2, 2, 1, 1, "Исходная информация")) -> Инв. №: 000410124.04.80191719 | C38: ="Инв. №: " & INDIRECT(ADDRESS(INT(ROUNDUP(((ROW())/6), 1)) + (2+'Исходная информация'!$N$2), 2, 1, 1, "Исходная информация")) -> Инв. №: 000410124.04.80191917 | E38: ="Инв. №: " & INDIRECT(ADDRESS(INT(ROUNDUP(((ROW())/6), 1)) + (2+'Исходная информация'!$N$3), 2, 1, 1, "Исходная информация")) -> Инв. №: 000410124.04.80191719
A39: ="Периодичность ТО: " & INDIRECT(ADDRESS(INT(ROUNDUP(((ROW())/6), 1)) + 2, 3, 1, 1, "Исходная информация")) -> Периодичность ТО: 12 мес | C39: ="Периодичность ТО: " & INDIRECT(ADDRESS(INT(ROUNDUP(((ROW())/6), 1)) + (2+'Исходная информация'!$N$2), 3, 1, 1, "Исходная информация")) -> Периодичность ТО: 12 мес | E39: ="Периодичность ТО: " & INDIRECT(ADDRESS(INT(ROUNDUP(((ROW())/6), 1)) + (2+'Исходная информация'!$N$3), 3, 1, 1, "Исходная информация")) -> Периодичность ТО: 12 мес
A40: ="Проведено ТО: " & INDIRECT(ADDRESS(INT(ROUNDUP(((ROW())/6), 1)) + 2, 4, 1, 1, "Исходная информация")) & " " & INDIRECT(ADDRESS(INT(ROUNDUP(((ROW())/6), 1)) + 2, 5, 1, 1, "Исходная информация")) & " г." -> Проведено ТО: Июль 2026 г. | C40: ="Проведено ТО: " & INDIRECT(ADDRESS(INT(ROUNDUP(((ROW())/6), 1)) + (2+'Исходная информация'!$N$2), 4, 1, 1, "Исходная информация")) & " " & INDIRECT(ADDRESS(INT(ROUNDUP(((ROW())/6), 1)) + (2+'Исходная информация'!$N$2), 5, 1, 1, "Исходная информация")) & " г." -> Проведено ТО: Июль 2026 г. | E40: ="Проведено ТО: " & INDIRECT(ADDRESS(INT(ROUNDUP(((ROW())/6), 1)) + (2+'Исходная информация'!$N$3), 4, 1, 1, "Исходная информация")) & " " & INDIRECT(ADDRESS(INT(ROUNDUP(((ROW())/6), 1)) + (2+'Исходная информация'!$N$3), 5, 1, 1, "Исходная информация")) & " г." -> Проведено ТО: Июль 2026 г.
...

Sheet BUG
A1: ="Наименование: " & INDIRECT(ADDRESS(INT(ROUNDUP(((ROW())/6), 1)) + (2+'Исходная информация'!$N$4), 1, 1, 1, "Исходная информация")) -> Наименование: Облучатель-рециркулятор воздуха ультрафиолетовый бактерицидный настенный ОРУБн-3-5-«КРОНТ» (Дезар-5) | C1: ="Наименование: " & INDIRECT(ADDRESS(INT(ROUNDUP(((ROW())/6), 1)) + (2+'Исходная информация'!$N$5), 1, 1, 1, "Исходная информация")) -> Наименование: Облучатель-рециркулятор воздуха ультрафиолетовый бактерицидный настенный ОРУБн-3-5-«КРОНТ» (Дезар-5) | E1: ="Наименование: " & INDIRECT(ADDRESS(INT(ROUNDUP(((ROW())/6), 1)) + 2, 1, 1, 1, "Исходная информация")) -> Наименование: Облучатель-рециркулятор воздуха ультрафиолетовый бактерицидный настенный ОРУБн-3-5-«КРОНТ» (Дезар-5)
A2: ="Инв. №: " & INDIRECT(ADDRESS(INT(ROUNDUP(((ROW())/6), 1)) + (2+'Исходная информация'!$N$4), 2, 1, 1, "Исходная информация")) -> Инв. №: 21647 | C2: ="Инв. №: " & INDIRECT(ADDRESS(INT(ROUNDUP(((ROW())/6), 1)) + (2+'Исходная информация'!$N$5), 2, 1, 1, "Исходная информация")) -> Инв. №: 21647 | E2: ="Инв. №: " & INDIRECT(ADDRESS(INT(ROUNDUP(((ROW())/6), 1)) + 2, 2, 1, 1, "Исходная информация")) -> Инв. №: 21647
A3: ="Периодичность ТО: " & INDIRECT(ADDRESS(INT(ROUNDUP(((ROW())/6), 1)) + (2+'Исходная информация'!$N$4), 3, 1, 1, "Исходная информация")) -> Периодичность ТО: 12 мес | C3: ="Периодичность ТО: " & INDIRECT(ADDRESS(INT(ROUNDUP(((ROW())/6), 1)) + (2+'Исходная информация'!$N$5), 3, 1, 1, "Исходная информация")) -> Периодичность ТО: 12 мес | E3: ="Периодичность ТО: " & INDIRECT(ADDRESS(INT(ROUNDUP(((ROW())/6), 1)) + 2, 3, 1, 1, "Исходная информация")) -> Периодичность ТО: 12 мес
A4: ="Проведено ТО: " & INDIRECT(ADDRESS(INT(ROUNDUP(((ROW())/6), 1)) + (2+'Исходная информация'!$N$4), 4, 1, 1, "Исходная информация")) & " " & INDIRECT(ADDRESS(INT(ROUNDUP(((ROW())/6), 1)) + (2+'Исходная информация'!$N$4), 5, 1, 1, "Исходная информация")) & " г." -> Проведено ТО: Июль 2026 г. | C4: ="Проведено ТО: " & INDIRECT(ADDRESS(INT(ROUNDUP(((ROW())/6), 1)) + (2+'Исходная информация'!$N$5), 4, 1, 1, "Исходная информация")) & " " & INDIRECT(ADDRESS(INT(ROUNDUP(((ROW())/6), 1)) + (2+'Исходная информация'!$N$5), 5, 1, 1, "Исходная информация")) & " г." -> Проведено ТО: Июль 2026 г. | E4: ="Проведено ТО: " & INDIRECT(ADDRESS(INT(ROUNDUP(((ROW())/6), 1)) + 2, 4, 1, 1, "Исходная информация")) & " " & INDIRECT(ADDRESS(INT(ROUNDUP(((ROW())/6), 1)) + 2, 5, 1, 1, "Исходная информация")) & " г." -> Проведено ТО: Июль 2026 г.
A5: ="Следующее ТО: " & INDIRECT(ADDRESS(INT(ROUNDUP(((ROW())/6), 1)) + (2+'Исходная информация'!$N$4), 9, 1, 1, "Исходная информация")) & " " & INDIRECT(ADDRESS(INT(ROUNDUP(((ROW())/6), 1)) + (2+'Исходная информация'!$N$4), 6, 1, 1, "Исходная информация")) & " г." -> Следующее ТО: Сентябрь 2027 г. | C5: ="Следующее ТО: " & INDIRECT(ADDRESS(INT(ROUNDUP(((ROW())/6), 1)) + (2+'Исходная информация'!$N$5), 9, 1, 1, "Исходная информация")) & " " & INDIRECT(ADDRESS(INT(ROUNDUP(((ROW())/6), 1)) + (2+'Исходная информация'!$N$5), 6, 1, 1, "Исходная информация")) & " г." -> Следующее ТО: Сентябрь 2027 г. | E5: ="Следующее ТО: " & INDIRECT(ADDRESS(INT(ROUNDUP(((ROW())/6), 1)) + 2, 9, 1, 1, "Исходная информация")) & " " & INDIRECT(ADDRESS(INT(ROUNDUP(((ROW())/6), 1)) + 2, 6, 1, 1, "Исходная информация")) & " г." -> Следующее ТО: Сентябрь 2027 г.
A6: ="Инженер ОЭиРМО: " & INDIRECT(ADDRESS(INT(ROUNDUP(((ROW())/6), 1)) + (2+'Исходная информация'!$N$4), 7, 1, 1, "Исходная информация")) -> Инженер ОЭиРМО: Данилова К.И. | C6: ="Инженер ОЭиРМО: " & INDIRECT(ADDRESS(INT(ROUNDUP(((ROW())/6), 1)) + (2+'Исходная информация'!$N$5), 7, 1, 1, "Исходная информация")) -> Инженер ОЭиРМО: Данилова К.И. | E6: ="Инженер ОЭиРМО: " & INDIRECT(ADDRESS(INT(ROUNDUP(((ROW())/6), 1)) + 2, 7, 1, 1, "Исходная информация")) -> Инженер ОЭиРМО: Данилова К.И.
A7: ="Наименование: " & INDIRECT(ADDRESS(INT(ROUNDUP(((ROW())/6), 1)) + (2+'Исходная информация'!$N$4), 1, 1, 1, "Исходная информация")) -> Наименование: Облучатель-рециркулятор воздуха ультрафиолетовый бактерицидный настенный ОРУБн-3-5-«КРОНТ» (Дезар-5) | C7: ="Наименование: " & INDIRECT(ADDRESS(INT(ROUNDUP(((ROW())/6), 1)) + (2+'Исходная информация'!$N$5), 1, 1, 1, "Исходная информация")) -> Наименование: Облучатель-рециркулятор воздуха ультрафиолетовый бактерицидный настенный ОРУБн-3-5-«КРОНТ» (Дезар-5) | E7: ="Наименование: " & INDIRECT(ADDRESS(INT(ROUNDUP(((ROW())/6), 1)) + (2+'Исходная информация'!$N$4), 1, 1, 1, "Исходная информация")) -> Наименование: Облучатель-рециркулятор воздуха ультрафиолетовый бактерицидный настенный ОРУБн-3-5-«КРОНТ» (Дезар-5)
A8: ="Инв. №: " & INDIRECT(ADDRESS(INT(ROUNDUP(((ROW())/6), 1)) + (2+'Исходная информация'!$N$4), 2, 1, 1, "Исходная информация")) -> Инв. №: 21648 | C8: ="Инв. №: " & INDIRECT(ADDRESS(INT(ROUNDUP(((ROW())/6), 1)) + (2+'Исходная информация'!$N$5), 2, 1, 1, "Исходная информация")) -> Инв. №: 21648 | E8: ="Инв. №: " & INDIRECT(ADDRESS(INT(ROUNDUP(((ROW())/6), 1)) + (2+'Исходная информация'!$N$4), 2, 1, 1, "Исходная информация")) -> Инв. №: 21648
A9: ="Периодичность ТО: " & INDIRECT(ADDRESS(INT(ROUNDUP(((ROW())/6), 1)) + (2+'Исходная информация'!$N$4), 3, 1, 1, "Исходная информация")) -> Периодичность ТО: 12 мес | C9: ="Периодичность ТО: " & INDIRECT(ADDRESS(INT(ROUNDUP(((ROW())/6), 1)) + (2+'Исходная информация'!$N$5), 3, 1, 1, "Исходная информация")) -> Периодичность ТО: 12 мес | E9: ="Периодичность ТО: " & INDIRECT(ADDRESS(INT(ROUNDUP(((ROW())/6), 1)) + (2+'Исходная информация'!$N$4), 3, 1, 1, "Исходная информация")) -> Периодичность ТО: 12 мес
A10: ="Проведено ТО: " & INDIRECT(ADDRESS(INT(ROUNDUP(((ROW())/6), 1)) + (2+'Исходная информация'!$N$4), 4, 1, 1, "Исходная информация")) & " " & INDIRECT(ADDRESS(INT(ROUNDUP(((ROW())/6), 1)) + (2+'Исходная информация'!$N$4), 5, 1, 1, "Исходная информация")) & " г." -> Проведено ТО: Июль 2026 г. | C10: ="Проведено ТО: " & INDIRECT(ADDRESS(INT(ROUNDUP(((ROW())/6), 1)) + (2+'Исходная информация'!$N$5), 4, 1, 1, "Исходная информация")) & " " & INDIRECT(ADDRESS(INT(ROUNDUP(((ROW())/6), 1)) + (2+'Исходная информация'!$N$5), 5, 1, 1, "Исходная информация")) & " г." -> Проведено ТО: Июль 2026 г. | E10: ="Проведено ТО: " & INDIRECT(ADDRESS(INT(ROUNDUP(((ROW())/6), 1)) + (2+'Исходная информация'!$N$4), 4, 1, 1, "Исходная информация")) & " " & INDIRECT(ADDRESS(INT(ROUNDUP(((ROW())/6), 1)) + (2+'Исходная информация'!$N$4), 5, 1, 1, "Исходная информация")) & " г." -> Проведено ТО: Июль 2026 г.
A11: ="Следующее ТО: " & INDIRECT(ADDRESS(INT(ROUNDUP(((ROW())/6), 1)) + (2+'Исходная информация'!$N$4), 9, 1, 1, "Исходная информация")) & " " & INDIRECT(ADDRESS(INT(ROUNDUP(((ROW())/6), 1)) + (2+'Исходная информация'!$N$4), 6, 1, 1, "Исходная информация")) & " г." -> Следующее ТО: Октябрь 2027 г. | C11: ="Следующее ТО: " & INDIRECT(ADDRESS(INT(ROUNDUP(((ROW())/6), 1)) + (2+'Исходная информация'!$N$5), 9, 1, 1, "Исходная информация")) & " " & INDIRECT(ADDRESS(INT(ROUNDUP(((ROW())/6), 1)) + (2+'Исходная информация'!$N$5), 6, 1, 1, "Исходная информация")) & " г." -> Следующее ТО: Октябрь 2027 г. | E11: ="Следующее ТО: " & INDIRECT(ADDRESS(INT(ROUNDUP(((ROW())/6), 1)) + (2+'Исходная информация'!$N$4), 4, 1, 1, "Исходная информация")) & " " & INDIRECT(ADDRESS(INT(ROUNDUP(((ROW())/6), 1)) + (2+'Исходная информация'!$N$4), 6, 1, 1, "Исходная информация")) & " г." -> Следующее ТО: Июль 2027 г.
A12: ="Инженер ОЭиРМО: " & INDIRECT(ADDRESS(INT(ROUNDUP(((ROW())/6), 1)) + (2+'Исходная информация'!$N$4), 7, 1, 1, "Исходная информация")) -> Инженер ОЭиРМО: Данилова К.И. | C12: ="Инженер ОЭиРМО: " & INDIRECT(ADDRESS(INT(ROUNDUP(((ROW())/6), 1)) + (2+'Исходная информация'!$N$5), 7, 1, 1, "Исходная информация")) -> Инженер ОЭиРМО: Данилова К.И. | E12: ="Инженер ОЭиРМО: " & INDIRECT(ADDRESS(INT(ROUNDUP(((ROW())/6), 1)) + (2+'Исходная информация'!$N$4), 7, 1, 1, "Исходная информация")) -> Инженер ОЭиРМО: Данилова К.И.
A13: ="Наименование: " & INDIRECT(ADDRESS(INT(ROUNDUP(((ROW())/6), 1)) + (2+'Исходная информация'!$N$4), 1, 1, 1, "Исходная информация")) -> Наименование: Облучатель-рециркулятор воздуха ультрафиолетовый бактерицидный настенный ОРУБн-3-5-«КРОНТ» (Дезар-5) | C13: ="Наименование: " & INDIRECT(ADDRESS(INT(ROUNDUP(((ROW())/6), 1)) + (2+'Исходная информация'!$N$4), 1, 1, 1, "Исходная информация")) -> Наименование: Облучатель-рециркулятор воздуха ультрафиолетовый бактерицидный настенный ОРУБн-3-5-«КРОНТ» (Дезар-5) | E13: ="Наименование: " & INDIRECT(ADDRESS(INT(ROUNDUP(((ROW())/6), 1)) + (2+'Исходная информация'!$N$4), 1, 1, 1, "Исходная информация")) -> Наименование: Облучатель-рециркулятор воздуха ультрафиолетовый бактерицидный настенный ОРУБн-3-5-«КРОНТ» (Дезар-5)
A14: ="Инв. №: " & INDIRECT(ADDRESS(INT(ROUNDUP(((ROW())/6), 1)) + (2+'Исходная информация'!$N$4), 2, 1, 1, "Исходная информация")) -> Инв. №: 21649 | C14: ="Инв. №: " & INDIRECT(ADDRESS(INT(ROUNDUP(((ROW())/6), 1)) + (2+'Исходная информация'!$N$4), 2, 1, 1, "Исходная информация")) -> Инв. №: 21649 | E14: ="Инв. №: " & INDIRECT(ADDRESS(INT(ROUNDUP(((ROW())/6), 1)) + (2+'Исходная информация'!$N$4), 2, 1, 1, "Исходная информация")) -> Инв. №: 21649
A15: ="Периодичность ТО: " & INDIRECT(ADDRESS(INT(ROUNDUP(((ROW())/6), 1)) + (2+'Исходная информация'!$N$4), 3, 1, 1, "Исходная информация")) -> Периодичность ТО: 12 мес | C15: ="Периодичность ТО: " & INDIRECT(ADDRESS(INT(ROUNDUP(((ROW())/6), 1)) + (2+'Исходная информация'!$N$4), 3, 1, 1, "Исходная информация")) -> Периодичность ТО: 12 мес | E15: ="Периодичность ТО: " & INDIRECT(ADDRESS(INT(ROUNDUP(((ROW())/6), 1)) + (2+'Исходная информация'!$N$4), 3, 1, 1, "Исходная информация")) -> Периодичность ТО: 12 мес
A16: ="Проведено ТО: " & INDIRECT(ADDRESS(INT(ROUNDUP(((ROW())/6), 1)) + (2+'Исходная информация'!$N$4), 4, 1, 1, "Исходная информация")) & " " & INDIRECT(ADDRESS(INT(ROUNDUP(((ROW())/6), 1)) + (2+'Исходная информация'!$N$4), 5, 1, 1, "Исходная информация")) & " г." -> Проведено ТО: Июль 2026 г. | C16: ="Проведено ТО: " & INDIRECT(ADDRESS(INT(ROUNDUP(((ROW())/6), 1)) + (2+'Исходная информация'!$N$4), 4, 1, 1, "Исходная информация")) & " " & INDIRECT(ADDRESS(INT(ROUNDUP(((ROW())/6), 1)) + (2+'Исходная информация'!$N$4), 5, 1, 1, "Исходная информация")) & " г." -> Проведено ТО: Июль 2026 г. | E16: ="Проведено ТО: " & INDIRECT(ADDRESS(INT(ROUNDUP(((ROW())/6), 1)) + (2+'Исходная информация'!$N$4), 4, 1, 1, "Исходная информация")) & " " & INDIRECT(ADDRESS(INT(ROUNDUP(((ROW())/6), 1)) + (2+'Исходная информация'!$N$4), 5, 1, 1, "Исходная информация")) & " г." -> Проведено ТО: Июль 2026 г.
A17: ="Следующее ТО: " & INDIRECT(ADDRESS(INT(ROUNDUP(((ROW())/6), 1)) + (2+'Исходная информация'!$N$4), 9, 1, 1, "Исходная информация")) & " " & INDIRECT(ADDRESS(INT(ROUNDUP(((ROW())/6), 1)) + (2+'Исходная информация'!$N$4), 6, 1, 1, "Исходная информация")) & " г." -> Следующее ТО: Ноябрь 2027 г. | C17: ="Следующее ТО: " & INDIRECT(ADDRESS(INT(ROUNDUP(((ROW())/6), 1)) + (2+'Исходная информация'!$N$4), 9, 1, 1, "Исходная информация")) & " " & INDIRECT(ADDRESS(INT(ROUNDUP(((ROW())/6), 1)) + (2+'Исходная информация'!$N$4), 6, 1, 1, "Исходная информация")) & " г." -> Следующее ТО: Ноябрь 2027 г. | E17: ="Следующее ТО: " & INDIRECT(ADDRESS(INT(ROUNDUP(((ROW())/6), 1)) + (2+'Исходная информация'!$N$4), 4, 1, 1, "Исходная информация")) & " " & INDIRECT(ADDRESS(INT(ROUNDUP(((ROW())/6), 1)) + (2+'Исходная информация'!$N$4), 6, 1, 1, "Исходная информация")) & " г." -> Следующее ТО: Июль 2027 г.
A18: ="Инженер ОЭиРМО: " & INDIRECT(ADDRESS(INT(ROUNDUP(((ROW())/6), 1)) + (2+'Исходная информация'!$N$4), 7, 1, 1, "Исходная информация")) -> Инженер ОЭиРМО: Данилова К.И. | C18: ="Инженер ОЭиРМО: " & INDIRECT(ADDRESS(INT(ROUNDUP(((ROW())/6), 1)) + (2+'Исходная информация'!$N$4), 7, 1, 1, "Исходная информация")) -> Инженер ОЭиРМО: Данилова К.И. | E18: ="Инженер ОЭиРМО: " & INDIRECT(ADDRESS(INT(ROUNDUP(((ROW())/6), 1)) + (2+'Исходная информация'!$N$4), 7, 1, 1, "Исходная информация")) -> Инженер ОЭиРМО: Данилова К.И.
A19: ="Наименование: " & INDIRECT(ADDRESS(INT(ROUNDUP(((ROW())/6), 1)) + (2+'Исходная информация'!$N$4), 1, 1, 1, "Исходная информация")) -> Наименование: Стол операционный с принадлежностями HY Base 3000. "Нанджин Миндрей Био-Медикал Электроникс Ко., Лтд." | C19: ="Наименование: " & INDIRECT(ADDRESS(INT(ROUNDUP(((ROW())/6), 1)) + (2+'Исходная информация'!$N$4), 1, 1, 1, "Исходная информация")) -> Наименование: Стол операционный с принадлежностями HY Base 3000. "Нанджин Миндрей Био-Медикал Электроникс Ко., Лтд." | E19: ="Наименование: " & INDIRECT(ADDRESS(INT(ROUNDUP(((ROW())/6), 1)) + (2+'Исходная информация'!$N$4), 1, 1, 1, "Исходная информация")) -> Наименование: Стол операционный с принадлежностями HY Base 3000. "Нанджин Миндрей Био-Медикал Электроникс Ко., Лтд."
A20: ="Инв. №: " & INDIRECT(ADDRESS(INT(ROUNDUP(((ROW())/6), 1)) + (2+'Исходная информация'!$N$4), 2, 1, 1, "Исходная информация")) -> Инв. №: 16917 | C20: ="Инв. №: " & INDIRECT(ADDRESS(INT(ROUNDUP(((ROW())/6), 1)) + (2+'Исходная информация'!$N$4), 2, 1, 1, "Исходная информация")) -> Инв. №: 16917 | E20: ="Инв. №: " & INDIRECT(ADDRESS(INT(ROUNDUP(((ROW())/6), 1)) + (2+'Исходная информация'!$N$4), 2, 1, 1, "Исходная информация")) -> Инв. №: 16917
A21: ="Периодичность ТО: " & INDIRECT(ADDRESS(INT(ROUNDUP(((ROW())/6), 1)) + (2+'Исходная информация'!$N$4), 3, 1, 1, "Исходная информация")) -> Периодичность ТО: 12 мес | C21: ="Периодичность ТО: " & INDIRECT(ADDRESS(INT(ROUNDUP(((ROW())/6), 1)) + (2+'Исходная информация'!$N$4), 3, 1, 1, "Исходная информация")) -> Периодичность ТО: 12 мес | E21: ="Периодичность ТО: " & INDIRECT(ADDRESS(INT(ROUNDUP(((ROW())/6), 1)) + (2+'Исходная информация'!$N$4), 3, 1, 1, "Исходная информация")) -> Периодичность ТО: 12 мес
A22: ="Проведено ТО: " & INDIRECT(ADDRESS(INT(ROUNDUP(((ROW())/6), 1)) + (2+'Исходная информация'!$N$4), 4, 1, 1, "Исходная информация")) & " " & INDIRECT(ADDRESS(INT(ROUNDUP(((ROW())/6), 1)) + (2+'Исходная информация'!$N$4), 5, 1, 1, "Исходная информация")) & " г." -> Проведено ТО: Июль 2026 г. | C22: ="Проведено ТО: " & INDIRECT(ADDRESS(INT(ROUNDUP(((ROW())/6), 1)) + (2+'Исходная информация'!$N$4), 4, 1, 1, "Исходная информация")) & " " & INDIRECT(ADDRESS(INT(ROUNDUP(((ROW())/6), 1)) + (2+'Исходная информация'!$N$4), 5, 1, 1, "Исходная информация")) & " г." -> Проведено ТО: Июль 2026 г. | E22: ="Проведено ТО: " & INDIRECT(ADDRESS(INT(ROUNDUP(((ROW())/6), 1)) + (2+'Исходная информация'!$N$4), 4, 1, 1, "Исходная информация")) & " " & INDIRECT(ADDRESS(INT(ROUNDUP(((ROW())/6), 1)) + (2+'Исходная информация'!$N$4), 5, 1, 1, "Исходная информация")) & " г." -> Проведено ТО: Июль 2026 г.
A23: ="Следующее ТО: " & INDIRECT(ADDRESS(INT(ROUNDUP(((ROW())/6), 1)) + (2+'Исходная информация'!$N$4), 9, 1, 1, "Исходная информация")) & " " & INDIRECT(ADDRESS(INT(ROUNDUP(((ROW())/6), 1)) + (2+'Исходная информация'!$N$4), 6, 1, 1, "Исходная информация")) & " г." -> Следующее ТО: Декабрь 2027 г. | C23: ="Следующее ТО: " & INDIRECT(ADDRESS(INT(ROUNDUP(((ROW())/6), 1)) + (2+'Исходная информация'!$N$4), 9, 1, 1, "Исходная информация")) & " " & INDIRECT(ADDRESS(INT(ROUNDUP(((ROW())/6), 1)) + (2+'Исходная информация'!$N$4), 6, 1, 1, "Исходная информация")) & " г." -> Следующее ТО: Декабрь 2027 г. | E23: ="Следующее ТО: " & INDIRECT(ADDRESS(INT(ROUNDUP(((ROW())/6), 1)) + (2+'Исходная информация'!$N$4), 4, 1, 1, "Исходная информация")) & " " & INDIRECT(ADDRESS(INT(ROUNDUP(((ROW())/6), 1)) + (2+'Исходная информация'!$N$4), 6, 1, 1, "Исходная информация")) & " г." -> Следующее ТО: Июль 2027 г.
A24: ="Инженер ОЭиРМО: " & INDIRECT(ADDRESS(INT(ROUNDUP(((ROW())/6), 1)) + (2+'Исходная информация'!$N$4), 7, 1, 1, "Исходная информация")) -> Инженер ОЭиРМО: Данилова К.И. | C24: ="Инженер ОЭиРМО: " & INDIRECT(ADDRESS(INT(ROUNDUP(((ROW())/6), 1)) + (2+'Исходная информация'!$N$4), 7, 1, 1, "Исходная информация")) -> Инженер ОЭиРМО: Данилова К.И. | E24: ="Инженер ОЭиРМО: " & INDIRECT(ADDRESS(INT(ROUNDUP(((ROW())/6), 1)) + (2+'Исходная информация'!$N$4), 7, 1, 1, "Исходная информация")) -> Инженер ОЭиРМО: Данилова К.И.
A25: ="Наименование: " & INDIRECT(ADDRESS(INT(ROUNDUP(((ROW())/6), 1)) + (2+'Исходная информация'!$N$4), 1, 1, 1, "Исходная информация")) -> Наименование: Стол операционный с принадлежностями HY Base 3000. "Нанджин Миндрей Био-Медикал Электроникс Ко., Лтд." | C25: ="Наименование: " & INDIRECT(ADDRESS(INT(ROUNDUP(((ROW())/6), 1)) + (2+'Исходная информация'!$N$4), 1, 1, 1, "Исходная информация")) -> Наименование: Стол операционный с принадлежностями HY Base 3000. "Нанджин Миндрей Био-Медикал Электроникс Ко., Лтд." | E25: ="Наименование: " & INDIRECT(ADDRESS(INT(ROUNDUP(((ROW())/6), 1)) + (2+'Исходная информация'!$N$4), 1, 1, 1, "Исходная информация")) -> Наименование: Стол операционный с принадлежностями HY Base 3000. "Нанджин Миндрей Био-Медикал Электроникс Ко., Лтд."
A26: ="Инв. №: " & INDIRECT(ADDRESS(INT(ROUNDUP(((ROW())/6), 1)) + (2+'Исходная информация'!$N$4), 2, 1, 1, "Исходная информация")) -> Инв. №: 16918 | C26: ="Инв. №: " & INDIRECT(ADDRESS(INT(ROUNDUP(((ROW())/6), 1)) + (2+'Исходная информация'!$N$4), 2, 1, 1, "Исходная информация")) -> Инв. №: 16918 | E26: ="Инв. №: " & INDIRECT(ADDRESS(INT(ROUNDUP(((ROW())/6), 1)) + (2+'Исходная информация'!$N$4), 2, 1, 1, "Исходная информация")) -> Инв. №: 16918
A27: ="Периодичность ТО: " & INDIRECT(ADDRESS(INT(ROUNDUP(((ROW())/6), 1)) + (2+'Исходная информация'!$N$4), 3, 1, 1, "Исходная информация")) -> Периодичность ТО: 12 мес | C27: ="Периодичность ТО: " & INDIRECT(ADDRESS(INT(ROUNDUP(((ROW())/6), 1)) + (2+'Исходная информация'!$N$4), 3, 1, 1, "Исходная информация")) -> Периодичность ТО: 12 мес | E27: ="Периодичность ТО: " & INDIRECT(ADDRESS(INT(ROUNDUP(((ROW())/6), 1)) + (2+'Исходная информация'!$N$4), 3, 1, 1, "Исходная информация")) -> Периодичность ТО: 12 мес
A28: ="Проведено ТО: " & INDIRECT(ADDRESS(INT(ROUNDUP(((ROW())/6), 1)) + (2+'Исходная информация'!$N$4), 4, 1, 1, "Исходная информация")) & " " & INDIRECT(ADDRESS(INT(ROUNDUP(((ROW())/6), 1)) + (2+'Исходная информация'!$N$4), 5, 1, 1, "Исходная информация")) & " г." -> Проведено ТО: Июль 2026 г. | C28: ="Проведено ТО: " & INDIRECT(ADDRESS(INT(ROUNDUP(((ROW())/6), 1)) + (2+'Исходная информация'!$N$4), 4, 1, 1, "Исходная информация")) & " " & INDIRECT(ADDRESS(INT(ROUNDUP(((ROW())/6), 1)) + (2+'Исходная информация'!$N$4), 5, 1, 1, "Исходная информация")) & " г." -> Проведено ТО: Июль 2026 г. | E28: ="Проведено ТО: " & INDIRECT(ADDRESS(INT(ROUNDUP(((ROW())/6), 1)) + (2+'Исходная информация'!$N$4), 4, 1, 1, "Исходная информация")) & " " & INDIRECT(ADDRESS(INT(ROUNDUP(((ROW())/6), 1)) + (2+'Исходная информация'!$N$4), 5, 1, 1, "Исходная информация")) & " г." -> Проведено ТО: Июль 2026 г.
A29: ="Следующее ТО: " & INDIRECT(ADDRESS(INT(ROUNDUP(((ROW())/6), 1)) + (2+'Исходная информация'!$N$4), 9, 1, 1, "Исходная информация")) & " " & INDIRECT(ADDRESS(INT(ROUNDUP(((ROW())/6), 1)) + (2+'Исходная информация'!$N$4), 6, 1, 1, "Исходная информация")) & " г." -> Следующее ТО: Январь 2027 г. | C29: ="Следующее ТО: " & INDIRECT(ADDRESS(INT(ROUNDUP(((ROW())/6), 1)) + (2+'Исходная информация'!$N$4), 9, 1, 1, "Исходная информация")) & " " & INDIRECT(ADDRESS(INT(ROUNDUP(((ROW())/6), 1)) + (2+'Исходная информация'!$N$4), 6, 1, 1, "Исходная информация")) & " г." -> Следующее ТО: Январь 2027 г. | E29: ="Следующее ТО: " & INDIRECT(ADDRESS(INT(ROUNDUP(((ROW())/6), 1)) + (2+'Исходная информация'!$N$4), 4, 1, 1, "Исходная информация")) & " " & INDIRECT(ADDRESS(INT(ROUNDUP(((ROW())/6), 1)) + (2+'Исходная информация'!$N$4), 6, 1, 1, "Исходная информация")) & " г." -> Следующее ТО: Июль 2027 г.
A30: ="Инженер ОЭиРМО: " & INDIRECT(ADDRESS(INT(ROUNDUP(((ROW())/6), 1)) + (2+'Исходная информация'!$N$4), 7, 1, 1, "Исходная информация")) -> Инженер ОЭиРМО: Данилова К.И. | C30: ="Инженер ОЭиРМО: " & INDIRECT(ADDRESS(INT(ROUNDUP(((ROW())/6), 1)) + (2+'Исходная информация'!$N$4), 7, 1, 1, "Исходная информация")) -> Инженер ОЭиРМО: Данилова К.И. | E30: ="Инженер ОЭиРМО: " & INDIRECT(ADDRESS(INT(ROUNDUP(((ROW())/6), 1)) + (2+'Исходная информация'!$N$4), 7, 1, 1, "Исходная информация")) -> Инженер ОЭиРМО: Данилова К.И.
A31: ="Наименование: " & INDIRECT(ADDRESS(INT(ROUNDUP(((ROW())/6), 1)) + (2+'Исходная информация'!$N$4), 1, 1, 1, "Исходная информация")) -> Наименование: Устройство для запаивания пакетов (390 Вт) | C31: ="Наименование: " & INDIRECT(ADDRESS(INT(ROUNDUP(((ROW())/6), 1)) + (2+'Исходная информация'!$N$4), 1, 1, 1, "Исходная информация")) -> Наименование: Устройство для запаивания пакетов (390 Вт) | E31: ="Наименование: " & INDIRECT(ADDRESS(INT(ROUNDUP(((ROW())/6), 1)) + (2+'Исходная информация'!$N$4), 1, 1, 1, "Исходная информация")) -> Наименование: Устройство для запаивания пакетов (390 Вт)
A32: ="Инв. №: " & INDIRECT(ADDRESS(INT(ROUNDUP(((ROW())/6), 1)) + (2+'Исходная информация'!$N$4), 2, 1, 1, "Исходная информация")) -> Инв. №: 27823 | C32: ="Инв. №: " & INDIRECT(ADDRESS(INT(ROUNDUP(((ROW())/6), 1)) + (2+'Исходная информация'!$N$4), 2, 1, 1, "Исходная информация")) -> Инв. №: 27823 | E32: ="Инв. №: " & INDIRECT(ADDRESS(INT(ROUNDUP(((ROW())/6), 1)) + (2+'Исходная информация'!$N$4), 2, 1, 1, "Исходная информация")) -> Инв. №: 27823
A33: ="Периодичность ТО: " & INDIRECT(ADDRESS(INT(ROUNDUP(((ROW())/6), 1)) + (2+'Исходная информация'!$N$4), 3, 1, 1, "Исходная информация")) -> Периодичность ТО: 12 мес | C33: ="Периодичность ТО: " & INDIRECT(ADDRESS(INT(ROUNDUP(((ROW())/6), 1)) + (2+'Исходная информация'!$N$4), 3, 1, 1, "Исходная информация")) -> Периодичность ТО: 12 мес | E33: ="Периодичность ТО: " & INDIRECT(ADDRESS(INT(ROUNDUP(((ROW())/6), 1)) + (2+'Исходная информация'!$N$4), 3, 1, 1, "Исходная информация")) -> Периодичность ТО: 12 мес
A34: ="Проведено ТО: " & INDIRECT(ADDRESS(INT(ROUNDUP(((ROW())/6), 1)) + (2+'Исходная информация'!$N$4), 4, 1, 1, "Исходная информация")) & " " & INDIRECT(ADDRESS(INT(ROUNDUP(((ROW())/6), 1)) + (2+'Исходная информация'!$N$4), 5, 1, 1, "Исходная информация")) & " г." -> Проведено ТО: Июль 2026 г. | C34: ="Проведено ТО: " & INDIRECT(ADDRESS(INT(ROUNDUP(((ROW())/6), 1)) + (2+'Исходная информация'!$N$4), 4, 1, 1, "Исходная информация")) & " " & INDIRECT(ADDRESS(INT(ROUNDUP(((ROW())/6), 1)) + (2+'Исходная информация'!$N$4), 5, 1, 1, "Исходная информация")) & " г." -> Проведено ТО: Июль 2026 г. | E34: ="Проведено ТО: " & INDIRECT(ADDRESS(INT(ROUNDUP(((ROW())/6), 1)) + (2+'Исходная информация'!$N$4), 4, 1, 1, "Исходная информация")) & " " & INDIRECT(ADDRESS(INT(ROUNDUP(((ROW())/6), 1)) + (2+'Исходная информация'!$N$4), 5, 1, 1, "Исходная информация")) & " г." -> Проведено ТО: Июль 2026 г.
A35: ="Следующее ТО: " & INDIRECT(ADDRESS(INT(ROUNDUP(((ROW())/6), 1)) + (2+'Исходная информация'!$N$4), 9, 1, 1, "Исходная информация")) & " " & INDIRECT(ADDRESS(INT(ROUNDUP(((ROW())/6), 1)) + (2+'Исходная информация'!$N$4), 6, 1, 1, "Исходная информация")) & " г." -> Следующее ТО: Февраль 2027 г. | C35: ="Следующее ТО: " & INDIRECT(ADDRESS(INT(ROUNDUP(((ROW())/6), 1)) + (2+'Исходная информация'!$N$4), 9, 1, 1, "Исходная информация")) & " " & INDIRECT(ADDRESS(INT(ROUNDUP(((ROW())/6), 1)) + (2+'Исходная информация'!$N$4), 6, 1, 1, "Исходная информация")) & " г." -> Следующее ТО: Февраль 2027 г. | E35: ="Следующее ТО: " & INDIRECT(ADDRESS(INT(ROUNDUP(((ROW())/6), 1)) + (2+'Исходная информация'!$N$4), 4, 1, 1, "Исходная информация")) & " " & INDIRECT(ADDRESS(INT(ROUNDUP(((ROW())/6), 1)) + (2+'Исходная информация'!$N$4), 6, 1, 1, "Исходная информация")) & " г." -> Следующее ТО: Июль 2027 г.
A36: ="Инженер ОЭиРМО: " & INDIRECT(ADDRESS(INT(ROUNDUP(((ROW())/6), 1)) + (2+'Исходная информация'!$N$4), 7, 1, 1, "Исходная информация")) -> Инженер ОЭиРМО: Данилова К.И. | C36: ="Инженер ОЭиРМО: " & INDIRECT(ADDRESS(INT(ROUNDUP(((ROW())/6), 1)) + (2+'Исходная информация'!$N$4), 7, 1, 1, "Исходная информация")) -> Инженер ОЭиРМО: Данилова К.И. | E36: ="Инженер ОЭиРМО: " & INDIRECT(ADDRESS(INT(ROUNDUP(((ROW())/6), 1)) + (2+'Исходная информация'!$N$4), 7, 1, 1, "Исходная информация")) -> Инженер ОЭиРМО: Данилова К.И.
A37: ="Наименование: " & INDIRECT(ADDRESS(INT(ROUNDUP(((ROW())/6), 1)) + (2+'Исходная информация'!$N$4), 1, 1, 1, "Исходная информация")) -> Наименование: аппарат высокочастотный электрохирургический | C37: ="Наименование: " & INDIRECT(ADDRESS(INT(ROUNDUP(((ROW())/6), 1)) + (2+'Исходная информация'!$N$4), 1, 1, 1, "Исходная информация")) -> Наименование: аппарат высокочастотный электрохирургический | E37: ="Наименование: " & INDIRECT(ADDRESS(INT(ROUNDUP(((ROW())/6), 1)) + (2+'Исходная информация'!$N$4), 1, 1, 1, "Исходная информация")) -> Наименование: аппарат высокочастотный электрохирургический
