Workbook

Sheet Исходная информация
A1: Наименование оборудования | B1: Инвентарный номер | C1: Периодичность ТО | D1: График ТО | E1: Год сейчас | F1: Год следующий | G1: Инженер | H1: # | I1: Месяц следующее ТО | M1: Опции
A2: Центрифуга Rotofix32 | B2: 000410124.04.80191116 | C2: 1 год | D2: Октябрь | E2: 2024 | F2: =E2+1 -> 2025 | H2: 1 | I2: =Таблица1[[#This Row],[График ТО]] -> Октябрь | M2: Offset | N2: 8
A3: Монитор глубины наркоза и седации А-2000XP на основе биспектрального ЭЭГ-индекса (BIS) | B3: 000410124.04.80191242 | C3: 1 год | D3: Октябрь | E3: 2024 | F3: =E3+1 -> 2025 | G3: Тангиров А.Р. | H3: 2 | I3: =Таблица1[[#This Row],[График ТО]] -> Октябрь | M3: Offset 2 | N3: =2*N2 -> 16
A4: Монитор глубины наркоза и седации А-2000XP на основе биспектрального ЭЭГ-индекса (BIS) | B4: 000410124.04.80191243 | C4: 1 год | D4: Октябрь | E4: 2024 | F4: =E4+1 -> 2025 | G4: Игнатов А.Е. | H4: 3 | I4: =Таблица1[[#This Row],[График ТО]] -> Октябрь | M4: Offset 3 | N4: =3*N2 -> 24
A5: аппарат для быстрого размораживания плазмы | B5: 000410124.04.80191753 | C5: 1 год | D5: Октябрь | E5: 2024 | F5: =E5+1 -> 2025 | G5: Игнатов А.Е. | H5: 4 | I5: =Таблица1[[#This Row],[График ТО]] -> Октябрь | M5: Offset 4 | N5: =24+8 -> 32
A6: монитор для определения сердечного выброса неинвазивным методом NIKO | B6: 000410124.04.80191668 | C6: 1 год | D6: Октябрь | E6: 2024 | F6: =E6+1 -> 2025 | G6: Тангиров А.Р. | H6: 5 | I6: =Таблица1[[#This Row],[График ТО]] -> Октябрь
A7: монитор для определения сердечного выброса неинвазивным методом NIСO | B7: 000410124.04.80191898 | C7: 1 год | D7: Октябрь | E7: 2024 | F7: =E7+1 -> 2025 | G7: Игнатов А.Е. | H7: 6 | I7: =Таблица1[[#This Row],[График ТО]] -> Октябрь
A8: аппарат для подогрева крови | B8: 000410124.04.80191755 | C8: 1 год | D8: Октябрь | E8: 2024 | F8: =E8+1 -> 2025 | G8: Игнатов А.Е. | H8: 7 | I8: =Таблица1[[#This Row],[График ТО]] -> Октябрь
A9: аппарат искусственной вентиляции легких высокочастотный струйный ИВЛ-ВЧ/100 «ЗисЛайн» | B9: 000410124.04.80191717 | C9: 1 год | D9: Октябрь | E9: 2024 | F9: =E9+1 -> 2025 | G9: Игнатов А.Е. | H9: 8 | I9: =Таблица1[[#This Row],[График ТО]] -> Октябрь
A10: аппарат для подогрева крови | B10: 000410124.04.80191758 | C10: 1 год | D10: Октябрь | E10: 2024 | F10: =E10+1 -> 2025 | G10: Костерин М.И. | H10: 9 | I10: =Таблица1[[#This Row],[График ТО]] -> Октябрь
A11: монитор пациента Vista русифицированный | B11: 000410124.04.5813 | C11: 1 год | D11: Октябрь | E11: 2024 | F11: =E11+1 -> 2025 | G11: Тангиров А.Р. | H11: 10 | I11: =Таблица1[[#This Row],[График ТО]] -> Октябрь
A12: монитор пациента Vista русифицированный | B12: 000410124.04.5815 | C12: 1 год | D12: Октябрь | E12: 2024 | F12: =E12+1 -> 2025 | G12: Игнатов А.Е. | H12: 11 | I12: =Таблица1[[#This Row],[График ТО]] -> Октябрь
A13: система для обогрева пациента WarmTouch | B13: 000410124.04.80191735 | C13: 1 год | D13: Октябрь | E13: 2024 | F13: =E13+1 -> 2025 | G13: Игнатов А.Е. | H13: 12 | I13: =Таблица1[[#This Row],[График ТО]] -> Октябрь
A14: система для обогрева пациента WarmTouch | B14: 000410124.04.80191736 | C14: 1 год | D14: Октябрь | E14: 2024 | F14: =E14+1 -> 2025 | G14: Тангиров А.Р. | H14: 13 | I14: =Таблица1[[#This Row],[График ТО]] -> Октябрь
A15: устройство для обогрева пациента | B15: 000410124.04.80191544 | C15: 1 год | D15: Октябрь | E15: 2024 | F15: =E15+1 -> 2025 | G15: Тангиров А.Р. | H15: 14 | I15: =Таблица1[[#This Row],[График ТО]] -> Октябрь
A16: Размораживатель плазмы ЭРП-4-01 | B16: 00410124.04.80191120 | C16: 1 год | D16: Октябрь | E16: 2024 | F16: =E16+1 -> 2025 | G16: Тангиров А.Р. | H16: 15 | I16: =Таблица1[[#This Row],[График ТО]] -> Октябрь
A17: Размораживатель плазмы крови ЭРП-4-01 | B17: 00410124.04.80191079 | C17: 1 год | D17: Октябрь | E17: 2024 | F17: =E17+1 -> 2025 | G17: Тангиров А.Р. | H17: 16 | I17: =Таблица1[[#This Row],[График ТО]] -> Октябрь
A18: Перемешиватель тромбоцитов на 15 доз PF 15h | B18: 14154 | C18: 1 год | D18: Октябрь | E18: 2024 | F18: =E18+1 -> 2025 | G18: Тангиров А.Р. | H18: 17 | I18: =Таблица1[[#This Row],[График ТО]] -> Октябрь
A19: Инкубатор для одного перемешивателя тромбоцитов на 15 доз РС 1 | B19: 14153 | C19: 1 год | D19: Октябрь | E19: 2024 | F19: =E19+1 -> 2025 | G19: Тангиров А.Р. | H19: 18 | I19: =Таблица1[[#This Row],[График ТО]] -> Октябрь
A20: Прибор поиска нервных сплетений при регионарной анестезии MultiStimSwitch | B20: 4836 | C20: 1 год | D20: Октябрь | E20: 2024 | F20: =E20+1 -> 2025 | G20: Тангиров А.Р. | H20: 19 | I20: =Таблица1[[#This Row],[График ТО]] -> Октябрь
A21: монитор мультипараметрический | B21: 004410124.04.101 | C21: 1 год | D21: Октябрь | E21: 2024 | F21: =E21+1 -> 2025 | G21: Тангиров А.Р. | H21: 20 | I21: =Таблица1[[#This Row],[График ТО]] -> Октябрь
A22: монитор мультипараметрический анестезиолога IntelliVueMP40 | B22: 004410124.04.102 | C22: 1 год | D22: Октябрь | E22: 2024 | F22: =E22+1 -> 2025 | G22: Игнатов А.Е. | H22: 21 | I22: =Таблица1[[#This Row],[График ТО]] -> Октябрь
A23: Монитор глубины наркоза и седации А-2000 ХР с системой измерения биспектрального индекса (Вis ) | B23: 004410124.04.110 | C23: 1 год | D23: Октябрь | E23: 2024 | F23: =E23+1 -> 2025 | G23: Игнатов А.Е. | H23: 22 | I23: =Таблица1[[#This Row],[График ТО]] -> Октябрь
A24: Монитор глубины наркоза и седации А-2000 ХР с системой измерения биспектрального индекса (Вis ) | B24: 004410124.04.111 | C24: 1 год | D24: Октябрь | E24: 2024 | F24: =E24+1 -> 2025 | G24: Игнатов А.Е. | H24: 23 | I24: =Таблица1[[#This Row],[График ТО]] -> Октябрь
A25: Монитор глубины наркоза и седации А-2000 ХР с системой измерения биспектрального индекса (Вis ) | B25: 004410124.04.112 | C25: 1 год | D25: Октябрь | E25: 2024 | F25: =E25+1 -> 2025 | G25: Игнатов А.Е. | H25: 24 | I25: =Таблица1[[#This Row],[График ТО]] -> Октябрь
A26: Монитор глубины наркоза и седации А-2000 ХР с системой измерения биспектрального индекса (Вis ) | B26: 004410124.04.113 | C26: 1 год | D26: Октябрь | E26: 2024 | F26: =E26+1 -> 2025 | G26: Игнатов А.Е. | H26: 25 | I26: =Таблица1[[#This Row],[График ТО]] -> Октябрь
A27: Монитор глубины наркоза и седации А-2000 ХР с системой измерения биспектрального индекса (Вis ) | B27: 004410124.04.114 | C27: 1 год | D27: Октябрь | E27: 2024 | F27: =E27+1 -> 2025 | G27: Игнатов А.Е. | H27: 26 | I27: =Таблица1[[#This Row],[График ТО]] -> Октябрь
A28: Монитор глубины наркоза и седации А-2000 ХР с системой измерения биспектрального индекса (Вis ) | B28: 004410124.04.115 | C28: 1 год | D28: Октябрь | E28: 2024 | F28: =E28+1 -> 2025 | G28: Игнатов А.Е. | H28: 27 | I28: =Таблица1[[#This Row],[График ТО]] -> Октябрь
A29: Монитор глубины наркоза и седации А-2000 ХР с системой измерения биспектрального индекса (Вis ) | B29: 004410124.04.116 | C29: 1 год | D29: Октябрь | E29: 2024 | F29: =E29+1 -> 2025 | G29: Игнатов А.Е. | H29: 28 | I29: =Таблица1[[#This Row],[График ТО]] -> Октябрь
A30: Монитор глубины наркоза и седации А-2000 ХР с системой измерения биспектрального индекса (Вis ) | B30: 004410124.04.117 | C30: 1 год | D30: Октябрь | E30: 2024 | F30: =E30+1 -> 2025 | G30: Игнатов А.Е. | H30: 29 | I30: =Таблица1[[#This Row],[График ТО]] -> Октябрь
A31: Монитор глубины наркоза и седации А-2000 ХР с системой измерения биспектрального индекса (Вis ) | B31: 004410124.04.118 | C31: 1 год | D31: Октябрь | E31: 2024 | F31: =E31+1 -> 2025 | G31: Игнатов А.Е. | H31: 30 | I31: =Таблица1[[#This Row],[График ТО]] -> Октябрь
A32: Монитор глубины наркоза и седации А-2000 ХР с системой измерения биспектрального индекса (Вis ) | B32: 004410124.04.119 | C32: 1 год | D32: Октябрь | E32: 2024 | F32: =E32+1 -> 2025 | G32: Игнатов А.Е. | H32: 31 | I32: =Таблица1[[#This Row],[График ТО]] -> Октябрь
... A49: дефибриллятор-монитор +карта+принадлежностиHeartStartXL | B49: 001410124.04.80191639 | C49: 1 год | D49: Октябрь | E49: 2024 | F49: =E49+1 -> 2025 | G49: Игнатов А.Е. | H49: 48 | I49: =Таблица1[[#This Row],[График ТО]] -> Октябрь
G50: Игнатов А.Е.

Sheet Первые 24
A1: ="Наименование: " & INDIRECT(ADDRESS(INT(ROUNDUP(((ROW())/6), 1)) + 2, 1, 1, 1, "Исходная информация")) -> Наименование: Центрифуга Rotofix32 | C1: ="Наименование: " & INDIRECT(ADDRESS(INT(ROUNDUP(((ROW())/6), 1)) + (2+'Исходная информация'!$N$2), 1, 1, 1, "Исходная информация")) -> Наименование: аппарат для подогрева крови | E1: ="Наименование: " & INDIRECT(ADDRESS(INT(ROUNDUP(((ROW())/6), 1)) + (2+'Исходная информация'!$N$3), 1, 1, 1, "Исходная информация")) -> Наименование: Перемешиватель тромбоцитов на 15 доз PF 15h
A2: ="Инв. №: " & INDIRECT(ADDRESS(INT(ROUNDUP(((ROW())/6), 1)) + 2, 2, 1, 1, "Исходная информация")) -> Инв. №: 000410124.04.80191116 | C2: ="Инв. №: " & INDIRECT(ADDRESS(INT(ROUNDUP(((ROW())/6), 1)) + (2+'Исходная информация'!$N$2), 2, 1, 1, "Исходная информация")) -> Инв. №: 000410124.04.80191758 | E2: ="Инв. №: " & INDIRECT(ADDRESS(INT(ROUNDUP(((ROW())/6), 1)) + (2+'Исходная информация'!$N$3), 2, 1, 1, "Исходная информация")) -> Инв. №: 14154
A3: ="Периодичность ТО: " & INDIRECT(ADDRESS(INT(ROUNDUP(((ROW())/6), 1)) + 2, 3, 1, 1, "Исходная информация")) -> Периодичность ТО: 1 год | C3: ="Периодичность ТО: " & INDIRECT(ADDRESS(INT(ROUNDUP(((ROW())/6), 1)) + (2+'Исходная информация'!$N$2), 3, 1, 1, "Исходная информация")) -> Периодичность ТО: 1 год | E3: ="Периодичность ТО: " & INDIRECT(ADDRESS(INT(ROUNDUP(((ROW())/6), 1)) + (2+'Исходная информация'!$N$3), 3, 1, 1, "Исходная информация")) -> Периодичность ТО: 1 год
A4: ="Проведено ТО: " & INDIRECT(ADDRESS(INT(ROUNDUP(((ROW())/6), 1)) + 2, 4, 1, 1, "Исходная информация")) & " " & INDIRECT(ADDRESS(INT(ROUNDUP(((ROW())/6), 1)) + 2, 5, 1, 1, "Исходная информация")) & " г." -> Проведено ТО: Октябрь 2024 г. | C4: ="Проведено ТО: " & INDIRECT(ADDRESS(INT(ROUNDUP(((ROW())/6), 1)) + (2+'Исходная информация'!$N$2), 4, 1, 1, "Исходная информация")) & " " & INDIRECT(ADDRESS(INT(ROUNDUP(((ROW())/6), 1)) + (2+'Исходная информация'!$N$2), 5, 1, 1, "Исходная информация")) & " г." -> Проведено ТО: Октябрь 2024 г. | E4: ="Проведено ТО: " & INDIRECT(ADDRESS(INT(ROUNDUP(((ROW())/6), 1)) + (2+'Исходная информация'!$N$3), 4, 1, 1, "Исходная информация")) & " " & INDIRECT(ADDRESS(INT(ROUNDUP(((ROW())/6), 1)) + (2+'Исходная информация'!$N$3), 5, 1, 1, "Исходная информация")) & " г." -> Проведено ТО: Октябрь 2024 г.
A5: ="Следующее ТО: " & INDIRECT(ADDRESS(INT(ROUNDUP(((ROW())/6), 1)) + 2, 9, 1, 1, "Исходная информация")) & " " & INDIRECT(ADDRESS(INT(ROUNDUP(((ROW())/6), 1)) + 2, 6, 1, 1, "Исходная информация")) & " г." -> Следующее ТО: Октябрь 2025 г. | C5: ="Следующее ТО: " & INDIRECT(ADDRESS(INT(ROUNDUP(((ROW())/6), 1)) + (2+'Исходная информация'!$N$2), 9, 1, 1, "Исходная информация")) & " " & INDIRECT(ADDRESS(INT(ROUNDUP(((ROW())/6), 1)) + (2+'Исходная информация'!$N$2), 6, 1, 1, "Исходная информация")) & " г." -> Следующее ТО: Октябрь 2025 г. | E5: ="Следующее ТО: " & INDIRECT(ADDRESS(INT(ROUNDUP(((ROW())/6), 1)) + (2+'Исходная информация'!$N$3), 9, 1, 1, "Исходная информация")) & " " & INDIRECT(ADDRESS(INT(ROUNDUP(((ROW())/6), 1)) + (2+'Исходная информация'!$N$3), 6, 1, 1, "Исходная информация")) & " г." -> Следующее ТО: Октябрь 2025 г.
A6: ="Инженер ОЭиРМО: " & INDIRECT(ADDRESS(INT(ROUNDUP(((ROW())/6), 1)) + 2, 7, 1, 1, "Исходная информация")) -> Инженер ОЭиРМО: Тангиров А.Р. | C6: ="Инженер ОЭиРМО: " & INDIRECT(ADDRESS(INT(ROUNDUP(((ROW())/6), 1)) + (2+'Исходная информация'!$N$2), 7, 1, 1, "Исходная информация")) -> Инженер ОЭиРМО: Тангиров А.Р. | E6: ="Инженер ОЭиРМО: " & INDIRECT(ADDRESS(INT(ROUNDUP(((ROW())/6), 1)) + (2+'Исходная информация'!$N$3), 7, 1, 1, "Исходная информация")) -> Инженер ОЭиРМО: Тангиров А.Р.
A7: ="Наименование: " & INDIRECT(ADDRESS(INT(ROUNDUP(((ROW())/6), 1)) + 2, 1, 1, 1, "Исходная информация")) -> Наименование: Монитор глубины наркоза и седации А-2000XP на основе биспектрального ЭЭГ-индекса (BIS) | C7: ="Наименование: " & INDIRECT(ADDRESS(INT(ROUNDUP(((ROW())/6), 1)) + (2+'Исходная информация'!$N$2), 1, 1, 1, "Исходная информация")) -> Наименование: монитор пациента Vista русифицированный | E7: ="Наименование: " & INDIRECT(ADDRESS(INT(ROUNDUP(((ROW())/6), 1)) + (2+'Исходная информация'!$N$3), 1, 1, 1, "Исходная информация")) -> Наименование: Инкубатор для одного перемешивателя тромбоцитов на 15 доз РС 1
A8: ="Инв. №: " & INDIRECT(ADDRESS(INT(ROUNDUP(((ROW())/6), 1)) + 2, 2, 1, 1, "Исходная информация")) -> Инв. №: 000410124.04.80191242 | C8: ="Инв. №: " & INDIRECT(ADDRESS(INT(ROUNDUP(((ROW())/6), 1)) + (2+'Исходная информация'!$N$2), 2, 1, 1, "Исходная информация")) -> Инв. №: 000410124.04.5813 | E8: ="Инв. №: " & INDIRECT(ADDRESS(INT(ROUNDUP(((ROW())/6), 1)) + (2+'Исходная информация'!$N$3), 2, 1, 1, "Исходная информация")) -> Инв. №: 14153
A9: ="Периодичность ТО: " & INDIRECT(ADDRESS(INT(ROUNDUP(((ROW())/6), 1)) + 2, 3, 1, 1, "Исходная информация")) -> Периодичность ТО: 1 год | C9: ="Периодичность ТО: " & INDIRECT(ADDRESS(INT(ROUNDUP(((ROW())/6), 1)) + (2+'Исходная информация'!$N$2), 3, 1, 1, "Исходная информация")) -> Периодичность ТО: 1 год | E9: ="Периодичность ТО: " & INDIRECT(ADDRESS(INT(ROUNDUP(((ROW())/6), 1)) + (2+'Исходная информация'!$N$3), 3, 1, 1, "Исходная информация")) -> Периодичность ТО: 1 год
A10: ="Проведено ТО: " & INDIRECT(ADDRESS(INT(ROUNDUP(((ROW())/6), 1)) + 2, 4, 1, 1, "Исходная информация")) & " " & INDIRECT(ADDRESS(INT(ROUNDUP(((ROW())/6), 1)) + 2, 5, 1, 1, "Исходная информация")) & " г." -> Проведено ТО: Октябрь 2024 г. | C10: ="Проведено ТО: " & INDIRECT(ADDRESS(INT(ROUNDUP(((ROW())/6), 1)) + (2+'Исходная информация'!$N$2), 4, 1, 1, "Исходная информация")) & " " & INDIRECT(ADDRESS(INT(ROUNDUP(((ROW())/6), 1)) + (2+'Исходная информация'!$N$2), 5, 1, 1, "Исходная информация")) & " г." -> Проведено ТО: Октябрь 2024 г. | E10: ="Проведено ТО: " & INDIRECT(ADDRESS(INT(ROUNDUP(((ROW())/6), 1)) + (2+'Исходная информация'!$N$3), 4, 1, 1, "Исходная информация")) & " " & INDIRECT(ADDRESS(INT(ROUNDUP(((ROW())/6), 1)) + (2+'Исходная информация'!$N$3), 5, 1, 1, "Исходная информация")) & " г." -> Проведено ТО: Октябрь 2024 г.
A11: ="Следующее ТО: " & INDIRECT(ADDRESS(INT(ROUNDUP(((ROW())/6), 1)) + 2, 9, 1, 1, "Исходная информация")) & " " & INDIRECT(ADDRESS(INT(ROUNDUP(((ROW())/6), 1)) + 2, 6, 1, 1, "Исходная информация")) & " г." -> Следующее ТО: Октябрь 2025 г. | C11: ="Следующее ТО: " & INDIRECT(ADDRESS(INT(ROUNDUP(((ROW())/6), 1)) + (2+'Исходная информация'!$N$2), 9, 1, 1, "Исходная информация")) & " " & INDIRECT(ADDRESS(INT(ROUNDUP(((ROW())/6), 1)) + (2+'Исходная информация'!$N$2), 6, 1, 1, "Исходная информация")) & " г." -> Следующее ТО: Октябрь 2025 г. | E11: ="Следующее ТО: " & INDIRECT(ADDRESS(INT(ROUNDUP(((ROW())/6), 1)) + (2+'Исходная информация'!$N$3), 9, 1, 1, "Исходная информация")) & " " & INDIRECT(ADDRESS(INT(ROUNDUP(((ROW())/6), 1)) + (2+'Исходная информация'!$N$3), 6, 1, 1, "Исходная информация")) & " г." -> Следующее ТО: Октябрь 2025 г.
A12: ="Инженер ОЭиРМО: " & INDIRECT(ADDRESS(INT(ROUNDUP(((ROW())/6), 1)) + 2, 7, 1, 1, "Исходная информация")) -> Инженер ОЭиРМО: Игнатов А.Е. | C12: ="Инженер ОЭиРМО: " & INDIRECT(ADDRESS(INT(ROUNDUP(((ROW())/6), 1)) + (2+'Исходная информация'!$N$2), 7, 1, 1, "Исходная информация")) -> Инженер ОЭиРМО: Игнатов А.Е. | E12: ="Инженер ОЭиРМО: " & INDIRECT(ADDRESS(INT(ROUNDUP(((ROW())/6), 1)) + (2+'Исходная информация'!$N$3), 7, 1, 1, "Исходная информация")) -> Инженер ОЭиРМО: Тангиров А.Р.
A13: ="Наименование: " & INDIRECT(ADDRESS(INT(ROUNDUP(((ROW())/6), 1)) + 2, 1, 1, 1, "Исходная информация")) -> Наименование: Монитор глубины наркоза и седации А-2000XP на основе биспектрального ЭЭГ-индекса (BIS) | C13: ="Наименование: " & INDIRECT(ADDRESS(INT(ROUNDUP(((ROW())/6), 1)) + (2+'Исходная информация'!$N$2), 1, 1, 1, "Исходная информация")) -> Наименование: монитор пациента Vista русифицированный | E13: ="Наименование: " & INDIRECT(ADDRESS(INT(ROUNDUP(((ROW())/6), 1)) + (2+'Исходная информация'!$N$3), 1, 1, 1, "Исходная информация")) -> Наименование: Прибор поиска нервных сплетений при регионарной анестезии MultiStimSwitch
A14: ="Инв. №: " & INDIRECT(ADDRESS(INT(ROUNDUP(((ROW())/6), 1)) + 2, 2, 1, 1, "Исходная информация")) -> Инв. №: 000410124.04.80191243 | C14: ="Инв. №: " & INDIRECT(ADDRESS(INT(ROUNDUP(((ROW())/6), 1)) + (2+'Исходная информация'!$N$2), 2, 1, 1, "Исходная информация")) -> Инв. №: 000410124.04.5815 | E14: ="Инв. №: " & INDIRECT(ADDRESS(INT(ROUNDUP(((ROW())/6), 1)) + (2+'Исходная информация'!$N$3), 2, 1, 1, "Исходная информация")) -> Инв. №: 4836
A15: ="Периодичность ТО: " & INDIRECT(ADDRESS(INT(ROUNDUP(((ROW())/6), 1)) + 2, 3, 1, 1, "Исходная информация")) -> Периодичность ТО: 1 год | C15: ="Периодичность ТО: " & INDIRECT(ADDRESS(INT(ROUNDUP(((ROW())/6), 1)) + (2+'Исходная информация'!$N$2), 3, 1, 1, "Исходная информация")) -> Периодичность ТО: 1 год | E15: ="Периодичность ТО: " & INDIRECT(ADDRESS(INT(ROUNDUP(((ROW())/6), 1)) + (2+'Исходная информация'!$N$3), 3, 1, 1, "Исходная информация")) -> Периодичность ТО: 1 год
A16: ="Проведено ТО: " & INDIRECT(ADDRESS(INT(ROUNDUP(((ROW())/6), 1)) + 2, 4, 1, 1, "Исходная информация")) & " " & INDIRECT(ADDRESS(INT(ROUNDUP(((ROW())/6), 1)) + 2, 5, 1, 1, "Исходная информация")) & " г." -> Проведено ТО: Октябрь 2024 г. | C16: ="Проведено ТО: " & INDIRECT(ADDRESS(INT(ROUNDUP(((ROW())/6), 1)) + (2+'Исходная информация'!$N$2), 4, 1, 1, "Исходная информация")) & " " & INDIRECT(ADDRESS(INT(ROUNDUP(((ROW())/6), 1)) + (2+'Исходная информация'!$N$2), 5, 1, 1, "Исходная информация")) & " г." -> Проведено ТО: Октябрь 2024 г. | E16: ="Проведено ТО: " & INDIRECT(ADDRESS(INT(ROUNDUP(((ROW())/6), 1)) + (2+'Исходная информация'!$N$3), 4, 1, 1, "Исходная информация")) & " " & INDIRECT(ADDRESS(INT(ROUNDUP(((ROW())/6), 1)) + (2+'Исходная информация'!$N$3), 5, 1, 1, "Исходная информация")) & " г." -> Проведено ТО: Октябрь 2024 г.
A17: ="Следующее ТО: " & INDIRECT(ADDRESS(INT(ROUNDUP(((ROW())/6), 1)) + 2, 9, 1, 1, "Исходная информация")) & " " & INDIRECT(ADDRESS(INT(ROUNDUP(((ROW())/6), 1)) + 2, 6, 1, 1, "Исходная информация")) & " г." -> Следующее ТО: Октябрь 2025 г. | C17: ="Следующее ТО: " & INDIRECT(ADDRESS(INT(ROUNDUP(((ROW())/6), 1)) + (2+'Исходная информация'!$N$2), 9, 1, 1, "Исходная информация")) & " " & INDIRECT(ADDRESS(INT(ROUNDUP(((ROW())/6), 1)) + (2+'Исходная информация'!$N$2), 6, 1, 1, "Исходная информация")) & " г." -> Следующее ТО: Октябрь 2025 г. | E17: ="Следующее ТО: " & INDIRECT(ADDRESS(INT(ROUNDUP(((ROW())/6), 1)) + (2+'Исходная информация'!$N$3), 9, 1, 1, "Исходная информация")) & " " & INDIRECT(ADDRESS(INT(ROUNDUP(((ROW())/6), 1)) + (2+'Исходная информация'!$N$3), 6, 1, 1, "Исходная информация")) & " г." -> Следующее ТО: Октябрь 2025 г.
A18: ="Инженер ОЭиРМО: " & INDIRECT(ADDRESS(INT(ROUNDUP(((ROW())/6), 1)) + 2, 7, 1, 1, "Исходная информация")) -> Инженер ОЭиРМО: Игнатов А.Е. | C18: ="Инженер ОЭиРМО: " & INDIRECT(ADDRESS(INT(ROUNDUP(((ROW())/6), 1)) + (2+'Исходная информация'!$N$2), 7, 1, 1, "Исходная информация")) -> Инженер ОЭиРМО: Игнатов А.Е. | E18: ="Инженер ОЭиРМО: " & INDIRECT(ADDRESS(INT(ROUNDUP(((ROW())/6), 1)) + (2+'Исходная информация'!$N$3), 7, 1, 1, "Исходная информация")) -> Инженер ОЭиРМО: Тангиров А.Р.
A19: ="Наименование: " & INDIRECT(ADDRESS(INT(ROUNDUP(((ROW())/6), 1)) + 2, 1, 1, 1, "Исходная информация")) -> Наименование: аппарат для быстрого размораживания плазмы | C19: ="Наименование: " & INDIRECT(ADDRESS(INT(ROUNDUP(((ROW())/6), 1)) + (2+'Исходная информация'!$N$2), 1, 1, 1, "Исходная информация")) -> Наименование: система для обогрева пациента WarmTouch | E19: ="Наименование: " & INDIRECT(ADDRESS(INT(ROUNDUP(((ROW())/6), 1)) + (2+'Исходная информация'!$N$3), 1, 1, 1, "Исходная информация")) -> Наименование: монитор мультипараметрический
A20: ="Инв. №: " & INDIRECT(ADDRESS(INT(ROUNDUP(((ROW())/6), 1)) + 2, 2, 1, 1, "Исходная информация")) -> Инв. №: 000410124.04.80191753 | C20: ="Инв. №: " & INDIRECT(ADDRESS(INT(ROUNDUP(((ROW())/6), 1)) + (2+'Исходная информация'!$N$2), 2, 1, 1, "Исходная информация")) -> Инв. №: 000410124.04.80191735 | E20: ="Инв. №: " & INDIRECT(ADDRESS(INT(ROUNDUP(((ROW())/6), 1)) + (2+'Исходная информация'!$N$3), 2, 1, 1, "Исходная информация")) -> Инв. №: 004410124.04.101
A21: ="Периодичность ТО: " & INDIRECT(ADDRESS(INT(ROUNDUP(((ROW())/6), 1)) + 2, 3, 1, 1, "Исходная информация")) -> Периодичность ТО: 1 год | C21: ="Периодичность ТО: " & INDIRECT(ADDRESS(INT(ROUNDUP(((ROW())/6), 1)) + (2+'Исходная информация'!$N$2), 3, 1, 1, "Исходная информация")) -> Периодичность ТО: 1 год | E21: ="Периодичность ТО: " & INDIRECT(ADDRESS(INT(ROUNDUP(((ROW())/6), 1)) + (2+'Исходная информация'!$N$3), 3, 1, 1, "Исходная информация")) -> Периодичность ТО: 1 год
A22: ="Проведено ТО: " & INDIRECT(ADDRESS(INT(ROUNDUP(((ROW())/6), 1)) + 2, 4, 1, 1, "Исходная информация")) & " " & INDIRECT(ADDRESS(INT(ROUNDUP(((ROW())/6), 1)) + 2, 5, 1, 1, "Исходная информация")) & " г." -> Проведено ТО: Октябрь 2024 г. | C22: ="Проведено ТО: " & INDIRECT(ADDRESS(INT(ROUNDUP(((ROW())/6), 1)) + (2+'Исходная информация'!$N$2), 4, 1, 1, "Исходная информация")) & " " & INDIRECT(ADDRESS(INT(ROUNDUP(((ROW())/6), 1)) + (2+'Исходная информация'!$N$2), 5, 1, 1, "Исходная информация")) & " г." -> Проведено ТО: Октябрь 2024 г. | E22: ="Проведено ТО: " & INDIRECT(ADDRESS(INT(ROUNDUP(((ROW())/6), 1)) + (2+'Исходная информация'!$N$3), 4, 1, 1, "Исходная информация")) & " " & INDIRECT(ADDRESS(INT(ROUNDUP(((ROW())/6), 1)) + (2+'Исходная информация'!$N$3), 5, 1, 1, "Исходная информация")) & " г." -> Проведено ТО: Октябрь 2024 г.
A23: ="Следующее ТО: " & INDIRECT(ADDRESS(INT(ROUNDUP(((ROW())/6), 1)) + 2, 9, 1, 1, "Исходная информация")) & " " & INDIRECT(ADDRESS(INT(ROUNDUP(((ROW())/6), 1)) + 2, 6, 1, 1, "Исходная информация")) & " г." -> Следующее ТО: Октябрь 2025 г. | C23: ="Следующее ТО: " & INDIRECT(ADDRESS(INT(ROUNDUP(((ROW())/6), 1)) + (2+'Исходная информация'!$N$2), 9, 1, 1, "Исходная информация")) & " " & INDIRECT(ADDRESS(INT(ROUNDUP(((ROW())/6), 1)) + (2+'Исходная информация'!$N$2), 6, 1, 1, "Исходная информация")) & " г." -> Следующее ТО: Октябрь 2025 г. | E23: ="Следующее ТО: " & INDIRECT(ADDRESS(INT(ROUNDUP(((ROW())/6), 1)) + (2+'Исходная информация'!$N$3), 9, 1, 1, "Исходная информация")) & " " & INDIRECT(ADDRESS(INT(ROUNDUP(((ROW())/6), 1)) + (2+'Исходная информация'!$N$3), 6, 1, 1, "Исходная информация")) & " г." -> Следующее ТО: Октябрь 2025 г.
A24: ="Инженер ОЭиРМО: " & INDIRECT(ADDRESS(INT(ROUNDUP(((ROW())/6), 1)) + 2, 7, 1, 1, "Исходная информация")) -> Инженер ОЭиРМО: Тангиров А.Р. | C24: ="Инженер ОЭиРМО: " & INDIRECT(ADDRESS(INT(ROUNDUP(((ROW())/6), 1)) + (2+'Исходная информация'!$N$2), 7, 1, 1, "Исходная информация")) -> Инженер ОЭиРМО: Тангиров А.Р. | E24: ="Инженер ОЭиРМО: " & INDIRECT(ADDRESS(INT(ROUNDUP(((ROW())/6), 1)) + (2+'Исходная информация'!$N$3), 7, 1, 1, "Исходная информация")) -> Инженер ОЭиРМО: Игнатов А.Е.
A25: ="Наименование: " & INDIRECT(ADDRESS(INT(ROUNDUP(((ROW())/6), 1)) + 2, 1, 1, 1, "Исходная информация")) -> Наименование: монитор для определения сердечного выброса неинвазивным методом NIKO | C25: ="Наименование: " & INDIRECT(ADDRESS(INT(ROUNDUP(((ROW())/6), 1)) + (2+'Исходная информация'!$N$2), 1, 1, 1, "Исходная информация")) -> Наименование: система для обогрева пациента WarmTouch | E25: ="Наименование: " & INDIRECT(ADDRESS(INT(ROUNDUP(((ROW())/6), 1)) + (2+'Исходная информация'!$N$3), 1, 1, 1, "Исходная информация")) -> Наименование: монитор мультипараметрический анестезиолога IntelliVueMP40
A26: ="Инв. №: " & INDIRECT(ADDRESS(INT(ROUNDUP(((ROW())/6), 1)) + 2, 2, 1, 1, "Исходная информация")) -> Инв. №: 000410124.04.80191668 | C26: ="Инв. №: " & INDIRECT(ADDRESS(INT(ROUNDUP(((ROW())/6), 1)) + (2+'Исходная информация'!$N$2), 2, 1, 1, "Исходная информация")) -> Инв. №: 000410124.04.80191736 | E26: ="Инв. №: " & INDIRECT(ADDRESS(INT(ROUNDUP(((ROW())/6), 1)) + (2+'Исходная информация'!$N$3), 2, 1, 1, "Исходная информация")) -> Инв. №: 004410124.04.102
A27: ="Периодичность ТО: " & INDIRECT(ADDRESS(INT(ROUNDUP(((ROW())/6), 1)) + 2, 3, 1, 1, "Исходная информация")) -> Периодичность ТО: 1 год | C27: ="Периодичность ТО: " & INDIRECT(ADDRESS(INT(ROUNDUP(((ROW())/6), 1)) + (2+'Исходная информация'!$N$2), 3, 1, 1, "Исходная информация")) -> Периодичность ТО: 1 год | E27: ="Периодичность ТО: " & INDIRECT(ADDRESS(INT(ROUNDUP(((ROW())/6), 1)) + (2+'Исходная информация'!$N$3), 3, 1, 1, "Исходная информация")) -> Периодичность ТО: 1 год
A28: ="Проведено ТО: " & INDIRECT(ADDRESS(INT(ROUNDUP(((ROW())/6), 1)) + 2, 4, 1, 1, "Исходная информация")) & " " & INDIRECT(ADDRESS(INT(ROUNDUP(((ROW())/6), 1)) + 2, 5, 1, 1, "Исходная информация")) & " г." -> Проведено ТО: Октябрь 2024 г. | C28: ="Проведено ТО: " & INDIRECT(ADDRESS(INT(ROUNDUP(((ROW())/6), 1)) + (2+'Исходная информация'!$N$2), 4, 1, 1, "Исходная информация")) & " " & INDIRECT(ADDRESS(INT(ROUNDUP(((ROW())/6), 1)) + (2+'Исходная информация'!$N$2), 5, 1, 1, "Исходная информация")) & " г." -> Проведено ТО: Октябрь 2024 г. | E28: ="Проведено ТО: " & INDIRECT(ADDRESS(INT(ROUNDUP(((ROW())/6), 1)) + (2+'Исходная информация'!$N$3), 4, 1, 1, "Исходная информация")) & " " & INDIRECT(ADDRESS(INT(ROUNDUP(((ROW())/6), 1)) + (2+'Исходная информация'!$N$3), 5, 1, 1, "Исходная информация")) & " г." -> Проведено ТО: Октябрь 2024 г.
A29: ="Следующее ТО: " & INDIRECT(ADDRESS(INT(ROUNDUP(((ROW())/6), 1)) + 2, 9, 1, 1, "Исходная информация")) & " " & INDIRECT(ADDRESS(INT(ROUNDUP(((ROW())/6), 1)) + 2, 6, 1, 1, "Исходная информация")) & " г." -> Следующее ТО: Октябрь 2025 г. | C29: ="Следующее ТО: " & INDIRECT(ADDRESS(INT(ROUNDUP(((ROW())/6), 1)) + (2+'Исходная информация'!$N$2), 9, 1, 1, "Исходная информация")) & " " & INDIRECT(ADDRESS(INT(ROUNDUP(((ROW())/6), 1)) + (2+'Исходная информация'!$N$2), 6, 1, 1, "Исходная информация")) & " г." -> Следующее ТО: Октябрь 2025 г. | E29: ="Следующее ТО: " & INDIRECT(ADDRESS(INT(ROUNDUP(((ROW())/6), 1)) + (2+'Исходная информация'!$N$3), 9, 1, 1, "Исходная информация")) & " " & INDIRECT(ADDRESS(INT(ROUNDUP(((ROW())/6), 1)) + (2+'Исходная информация'!$N$3), 6, 1, 1, "Исходная информация")) & " г." -> Следующее ТО: Октябрь 2025 г.
A30: ="Инженер ОЭиРМО: " & INDIRECT(ADDRESS(INT(ROUNDUP(((ROW())/6), 1)) + 2, 7, 1, 1, "Исходная информация")) -> Инженер ОЭиРМО: Игнатов А.Е. | C30: ="Инженер ОЭиРМО: " & INDIRECT(ADDRESS(INT(ROUNDUP(((ROW())/6), 1)) + (2+'Исходная информация'!$N$2), 7, 1, 1, "Исходная информация")) -> Инженер ОЭиРМО: Тангиров А.Р. | E30: ="Инженер ОЭиРМО: " & INDIRECT(ADDRESS(INT(ROUNDUP(((ROW())/6), 1)) + (2+'Исходная информация'!$N$3), 7, 1, 1, "Исходная информация")) -> Инженер ОЭиРМО: Игнатов А.Е.
A31: ="Наименование: " & INDIRECT(ADDRESS(INT(ROUNDUP(((ROW())/6), 1)) + 2, 1, 1, 1, "Исходная информация")) -> Наименование: монитор для определения сердечного выброса неинвазивным методом NIСO | C31: ="Наименование: " & INDIRECT(ADDRESS(INT(ROUNDUP(((ROW())/6), 1)) + (2+'Исходная информация'!$N$2), 1, 1, 1, "Исходная информация")) -> Наименование: устройство для обогрева пациента | E31: ="Наименование: " & INDIRECT(ADDRESS(INT(ROUNDUP(((ROW())/6), 1)) + (2+'Исходная информация'!$N$3), 1, 1, 1, "Исходная информация")) -> Наименование: Монитор глубины наркоза и седации А-2000 ХР с системой измерения биспектрального индекса (Вis )
A32: ="Инв. №: " & INDIRECT(ADDRESS(INT(ROUNDUP(((ROW())/6), 1)) + 2, 2, 1, 1, "Исходная информация")) -> Инв. №: 000410124.04.80191898 | C32: ="Инв. №: " & INDIRECT(ADDRESS(INT(ROUNDUP(((ROW())/6), 1)) + (2+'Исходная информация'!$N$2), 2, 1, 1, "Исходная информация")) -> Инв. №: 000410124.04.80191544 | E32: ="Инв. №: " & INDIRECT(ADDRESS(INT(ROUNDUP(((ROW())/6), 1)) + (2+'Исходная информация'!$N$3), 2, 1, 1, "Исходная информация")) -> Инв. №: 004410124.04.110
A33: ="Периодичность ТО: " & INDIRECT(ADDRESS(INT(ROUNDUP(((ROW())/6), 1)) + 2, 3, 1, 1, "Исходная информация")) -> Периодичность ТО: 1 год | C33: ="Периодичность ТО: " & INDIRECT(ADDRESS(INT(ROUNDUP(((ROW())/6), 1)) + (2+'Исходная информация'!$N$2), 3, 1, 1, "Исходная информация")) -> Периодичность ТО: 1 год | E33: ="Периодичность ТО: " & INDIRECT(ADDRESS(INT(ROUNDUP(((ROW())/6), 1)) + (2+'Исходная информация'!$N$3), 3, 1, 1, "Исходная информация")) -> Периодичность ТО: 1 год
A34: ="Проведено ТО: " & INDIRECT(ADDRESS(INT(ROUNDUP(((ROW())/6), 1)) + 2, 4, 1, 1, "Исходная информация")) & " " & INDIRECT(ADDRESS(INT(ROUNDUP(((ROW())/6), 1)) + 2, 5, 1, 1, "Исходная информация")) & " г." -> Проведено ТО: Октябрь 2024 г. | C34: ="Проведено ТО: " & INDIRECT(ADDRESS(INT(ROUNDUP(((ROW())/6), 1)) + (2+'Исходная информация'!$N$2), 4, 1, 1, "Исходная информация")) & " " & INDIRECT(ADDRESS(INT(ROUNDUP(((ROW())/6), 1)) + (2+'Исходная информация'!$N$2), 5, 1, 1, "Исходная информация")) & " г." -> Проведено ТО: Октябрь 2024 г. | E34: ="Проведено ТО: " & INDIRECT(ADDRESS(INT(ROUNDUP(((ROW())/6), 1)) + (2+'Исходная информация'!$N$3), 4, 1, 1, "Исходная информация")) & " " & INDIRECT(ADDRESS(INT(ROUNDUP(((ROW())/6), 1)) + (2+'Исходная информация'!$N$3), 5, 1, 1, "Исходная информация")) & " г." -> Проведено ТО: Октябрь 2024 г.
A35: ="Следующее ТО: " & INDIRECT(ADDRESS(INT(ROUNDUP(((ROW())/6), 1)) + 2, 9, 1, 1, "Исходная информация")) & " " & INDIRECT(ADDRESS(INT(ROUNDUP(((ROW())/6), 1)) + 2, 6, 1, 1, "Исходная информация")) & " г." -> Следующее ТО: Октябрь 2025 г. | C35: ="Следующее ТО: " & INDIRECT(ADDRESS(INT(ROUNDUP(((ROW())/6), 1)) + (2+'Исходная информация'!$N$2), 9, 1, 1, "Исходная информация")) & " " & INDIRECT(ADDRESS(INT(ROUNDUP(((ROW())/6), 1)) + (2+'Исходная информация'!$N$2), 6, 1, 1, "Исходная информация")) & " г." -> Следующее ТО: Октябрь 2025 г. | E35: ="Следующее ТО: " & INDIRECT(ADDRESS(INT(ROUNDUP(((ROW())/6), 1)) + (2+'Исходная информация'!$N$3), 9, 1, 1, "Исходная информация")) & " " & INDIRECT(ADDRESS(INT(ROUNDUP(((ROW())/6), 1)) + (2+'Исходная информация'!$N$3), 6, 1, 1, "Исходная информация")) & " г." -> Следующее ТО: Октябрь 2025 г.
A36: ="Инженер ОЭиРМО: " & INDIRECT(ADDRESS(INT(ROUNDUP(((ROW())/6), 1)) + 2, 7, 1, 1, "Исходная информация")) -> Инженер ОЭиРМО: Игнатов А.Е. | C36: ="Инженер ОЭиРМО: " & INDIRECT(ADDRESS(INT(ROUNDUP(((ROW())/6), 1)) + (2+'Исходная информация'!$N$2), 7, 1, 1, "Исходная информация")) -> Инженер ОЭиРМО: Тангиров А.Р. | E36: ="Инженер ОЭиРМО: " & INDIRECT(ADDRESS(INT(ROUNDUP(((ROW())/6), 1)) + (2+'Исходная информация'!$N$3), 7, 1, 1, "Исходная информация")) -> Инженер ОЭиРМО: Игнатов А.Е.
A37: ="Наименование: " & INDIRECT(ADDRESS(INT(ROUNDUP(((ROW())/6), 1)) + 2, 1, 1, 1, "Исходная информация")) -> Наименование: аппарат для подогрева крови | C37: ="Наименование: " & INDIRECT(ADDRESS(INT(ROUNDUP(((ROW())/6), 1)) + (2+'Исходная информация'!$N$2), 1, 1, 1, "Исходная информация")) -> Наименование: Размораживатель плазмы ЭРП-4-01 | E37: ="Наименование: " & INDIRECT(ADDRESS(INT(ROUNDUP(((ROW())/6), 1)) + (2+'Исходная информация'!$N$3), 1, 1, 1, "Исходная информация")) -> Наименование: Монитор глубины наркоза и седации А-2000 ХР с системой измерения биспектрального индекса (Вis )
A38: ="Инв. №: " & INDIRECT(ADDRESS(INT(ROUNDUP(((ROW())/6), 1)) + 2, 2, 1, 1, "Исходная информация")) -> Инв. №: 000410124.04.80191755 | C38: ="Инв. №: " & INDIRECT(ADDRESS(INT(ROUNDUP(((ROW())/6), 1)) + (2+'Исходная информация'!$N$2), 2, 1, 1, "Исходная информация")) -> Инв. №: 00410124.04.80191120 | E38: ="Инв. №: " & INDIRECT(ADDRESS(INT(ROUNDUP(((ROW())/6), 1)) + (2+'Исходная информация'!$N$3), 2, 1, 1, "Исходная информация")) -> Инв. №: 004410124.04.111
A39: ="Периодичность ТО: " & INDIRECT(ADDRESS(INT(ROUNDUP(((ROW())/6), 1)) + 2, 3, 1, 1, "Исходная информация")) -> Периодичность ТО: 1 год | C39: ="Периодичность ТО: " & INDIRECT(ADDRESS(INT(ROUNDUP(((ROW())/6), 1)) + (2+'Исходная информация'!$N$2), 3, 1, 1, "Исходная информация")) -> Периодичность ТО: 1 год | E39: ="Периодичность ТО: " & INDIRECT(ADDRESS(INT(ROUNDUP(((ROW())/6), 1)) + (2+'Исходная информация'!$N$3), 3, 1, 1, "Исходная информация")) -> Периодичность ТО: 1 год
A40: ="Проведено ТО: " & INDIRECT(ADDRESS(INT(ROUNDUP(((ROW())/6), 1)) + 2, 4, 1, 1, "Исходная информация")) & " " & INDIRECT(ADDRESS(INT(ROUNDUP(((ROW())/6), 1)) + 2, 5, 1, 1, "Исходная информация")) & " г." -> Проведено ТО: Октябрь 2024 г. | C40: ="Проведено ТО: " & INDIRECT(ADDRESS(INT(ROUNDUP(((ROW())/6), 1)) + (2+'Исходная информация'!$N$2), 4, 1, 1, "Исходная информация")) & " " & INDIRECT(ADDRESS(INT(ROUNDUP(((ROW())/6), 1)) + (2+'Исходная информация'!$N$2), 5, 1, 1, "Исходная информация")) & " г." -> Проведено ТО: Октябрь 2024 г. | E40: ="Проведено ТО: " & INDIRECT(ADDRESS(INT(ROUNDUP(((ROW())/6), 1)) + (2+'Исходная информация'!$N$3), 4, 1, 1, "Исходная информация")) & " " & INDIRECT(ADDRESS(INT(ROUNDUP(((ROW())/6), 1)) + (2+'Исходная информация'!$N$3), 5, 1, 1, "Исходная информация")) & " г." -> Проведено ТО: Октябрь 2024 г.
...

Sheet BUG
A1: ="Наименование: " & INDIRECT(ADDRESS(INT(ROUNDUP(((ROW())/6), 1)) + (2+'Исходная информация'!$N$4), 1, 1, 1, "Исходная информация")) -> Наименование: Монитор глубины наркоза и седации А-2000 ХР с системой измерения биспектрального индекса (Вis ) | C1: ="Наименование: " & INDIRECT(ADDRESS(INT(ROUNDUP(((ROW())/6), 1)) + (2+'Исходная информация'!$N$5), 1, 1, 1, "Исходная информация")) -> Наименование: аппарат реинфузии крови AUTOLOG | E1: ="Наименование: " & INDIRECT(ADDRESS(INT(ROUNDUP(((ROW())/6), 1)) + 2, 1, 1, 1, "Исходная информация")) -> Наименование: Центрифуга Rotofix32
A2: ="Инв. №: " & INDIRECT(ADDRESS(INT(ROUNDUP(((ROW())/6), 1)) + (2+'Исходная информация'!$N$4), 2, 1, 1, "Исходная информация")) -> Инв. №: 004410124.04.113 | C2: ="Инв. №: " & INDIRECT(ADDRESS(INT(ROUNDUP(((ROW())/6), 1)) + (2+'Исходная информация'!$N$5), 2, 1, 1, "Исходная информация")) -> Инв. №: 001410124.04.80192699 | E2: ="Инв. №: " & INDIRECT(ADDRESS(INT(ROUNDUP(((ROW())/6), 1)) + 2, 2, 1, 1, "Исходная информация")) -> Инв. №: 000410124.04.80191116
A3: ="Периодичность ТО: " & INDIRECT(ADDRESS(INT(ROUNDUP(((ROW())/6), 1)) + (2+'Исходная информация'!$N$4), 3, 1, 1, "Исходная информация")) -> Периодичность ТО: 1 год | C3: ="Периодичность ТО: " & INDIRECT(ADDRESS(INT(ROUNDUP(((ROW())/6), 1)) + (2+'Исходная информация'!$N$5), 3, 1, 1, "Исходная информация")) -> Периодичность ТО: 1 год | E3: ="Периодичность ТО: " & INDIRECT(ADDRESS(INT(ROUNDUP(((ROW())/6), 1)) + 2, 3, 1, 1, "Исходная информация")) -> Периодичность ТО: 1 год
A4: ="Проведено ТО: " & INDIRECT(ADDRESS(INT(ROUNDUP(((ROW())/6), 1)) + (2+'Исходная информация'!$N$4), 4, 1, 1, "Исходная информация")) & " " & INDIRECT(ADDRESS(INT(ROUNDUP(((ROW())/6), 1)) + (2+'Исходная информация'!$N$4), 5, 1, 1, "Исходная информация")) & " г." -> Проведено ТО: Октябрь 2024 г. | C4: ="Проведено ТО: " & INDIRECT(ADDRESS(INT(ROUNDUP(((ROW())/6), 1)) + (2+'Исходная информация'!$N$5), 4, 1, 1, "Исходная информация")) & " " & INDIRECT(ADDRESS(INT(ROUNDUP(((ROW())/6), 1)) + (2+'Исходная информация'!$N$5), 5, 1, 1, "Исходная информация")) & " г." -> Проведено ТО: Октябрь 2024 г. | E4: ="Проведено ТО: " & INDIRECT(ADDRESS(INT(ROUNDUP(((ROW())/6), 1)) + 2, 4, 1, 1, "Исходная информация")) & " " & INDIRECT(ADDRESS(INT(ROUNDUP(((ROW())/6), 1)) + 2, 5, 1, 1, "Исходная информация")) & " г." -> Проведено ТО: Октябрь 2024 г.
A5: ="Следующее ТО: " & INDIRECT(ADDRESS(INT(ROUNDUP(((ROW())/6), 1)) + (2+'Исходная информация'!$N$4), 9, 1, 1, "Исходная информация")) & " " & INDIRECT(ADDRESS(INT(ROUNDUP(((ROW())/6), 1)) + (2+'Исходная информация'!$N$4), 6, 1, 1, "Исходная информация")) & " г." -> Следующее ТО: Октябрь 2025 г. | C5: ="Следующее ТО: " & INDIRECT(ADDRESS(INT(ROUNDUP(((ROW())/6), 1)) + (2+'Исходная информация'!$N$5), 9, 1, 1, "Исходная информация")) & " " & INDIRECT(ADDRESS(INT(ROUNDUP(((ROW())/6), 1)) + (2+'Исходная информация'!$N$5), 6, 1, 1, "Исходная информация")) & " г." -> Следующее ТО: Октябрь 2025 г. | E5: ="Следующее ТО: " & INDIRECT(ADDRESS(INT(ROUNDUP(((ROW())/6), 1)) + 2, 9, 1, 1, "Исходная информация")) & " " & INDIRECT(ADDRESS(INT(ROUNDUP(((ROW())/6), 1)) + 2, 6, 1, 1, "Исходная информация")) & " г." -> Следующее ТО: Октябрь 2025 г.
A6: ="Инженер ОЭиРМО: " & INDIRECT(ADDRESS(INT(ROUNDUP(((ROW())/6), 1)) + (2+'Исходная информация'!$N$4), 7, 1, 1, "Исходная информация")) -> Инженер ОЭиРМО: Игнатов А.Е. | C6: ="Инженер ОЭиРМО: " & INDIRECT(ADDRESS(INT(ROUNDUP(((ROW())/6), 1)) + (2+'Исходная информация'!$N$5), 7, 1, 1, "Исходная информация")) -> Инженер ОЭиРМО: Тангиров А.Р. | E6: ="Инженер ОЭиРМО: " & INDIRECT(ADDRESS(INT(ROUNDUP(((ROW())/6), 1)) + 2, 7, 1, 1, "Исходная информация")) -> Инженер ОЭиРМО: Тангиров А.Р.
A7: ="Наименование: " & INDIRECT(ADDRESS(INT(ROUNDUP(((ROW())/6), 1)) + (2+'Исходная информация'!$N$4), 1, 1, 1, "Исходная информация")) -> Наименование: Монитор глубины наркоза и седации А-2000 ХР с системой измерения биспектрального индекса (Вis ) | C7: ="Наименование: " & INDIRECT(ADDRESS(INT(ROUNDUP(((ROW())/6), 1)) + (2+'Исходная информация'!$N$5), 1, 1, 1, "Исходная информация")) -> Наименование: дефибриллятор-монитор + пейсмейкер + пульсоксиметрияHeartStartXL | E7: ="Наименование: " & INDIRECT(ADDRESS(INT(ROUNDUP(((ROW())/6), 1)) + (2+'Исходная информация'!$N$4), 1, 1, 1, "Исходная информация")) -> Наименование: Монитор глубины наркоза и седации А-2000 ХР с системой измерения биспектрального индекса (Вis )
A8: ="Инв. №: " & INDIRECT(ADDRESS(INT(ROUNDUP(((ROW())/6), 1)) + (2+'Исходная информация'!$N$4), 2, 1, 1, "Исходная информация")) -> Инв. №: 004410124.04.114 | C8: ="Инв. №: " & INDIRECT(ADDRESS(INT(ROUNDUP(((ROW())/6), 1)) + (2+'Исходная информация'!$N$5), 2, 1, 1, "Исходная информация")) -> Инв. №: 001410124.04.80191650 | E8: ="Инв. №: " & INDIRECT(ADDRESS(INT(ROUNDUP(((ROW())/6), 1)) + (2+'Исходная информация'!$N$4), 2, 1, 1, "Исходная информация")) -> Инв. №: 004410124.04.114
A9: ="Периодичность ТО: " & INDIRECT(ADDRESS(INT(ROUNDUP(((ROW())/6), 1)) + (2+'Исходная информация'!$N$4), 3, 1, 1, "Исходная информация")) -> Периодичность ТО: 1 год | C9: ="Периодичность ТО: " & INDIRECT(ADDRESS(INT(ROUNDUP(((ROW())/6), 1)) + (2+'Исходная информация'!$N$5), 3, 1, 1, "Исходная информация")) -> Периодичность ТО: 1 год | E9: ="Периодичность ТО: " & INDIRECT(ADDRESS(INT(ROUNDUP(((ROW())/6), 1)) + (2+'Исходная информация'!$N$4), 3, 1, 1, "Исходная информация")) -> Периодичность ТО: 1 год
A10: ="Проведено ТО: " & INDIRECT(ADDRESS(INT(ROUNDUP(((ROW())/6), 1)) + (2+'Исходная информация'!$N$4), 4, 1, 1, "Исходная информация")) & " " & INDIRECT(ADDRESS(INT(ROUNDUP(((ROW())/6), 1)) + (2+'Исходная информация'!$N$4), 5, 1, 1, "Исходная информация")) & " г." -> Проведено ТО: Октябрь 2024 г. | C10: ="Проведено ТО: " & INDIRECT(ADDRESS(INT(ROUNDUP(((ROW())/6), 1)) + (2+'Исходная информация'!$N$5), 4, 1, 1, "Исходная информация")) & " " & INDIRECT(ADDRESS(INT(ROUNDUP(((ROW())/6), 1)) + (2+'Исходная информация'!$N$5), 5, 1, 1, "Исходная информация")) & " г." -> Проведено ТО: Октябрь 2024 г. | E10: ="Проведено ТО: " & INDIRECT(ADDRESS(INT(ROUNDUP(((ROW())/6), 1)) + (2+'Исходная информация'!$N$4), 4, 1, 1, "Исходная информация")) & " " & INDIRECT(ADDRESS(INT(ROUNDUP(((ROW())/6), 1)) + (2+'Исходная информация'!$N$4), 5, 1, 1, "Исходная информация")) & " г." -> Проведено ТО: Октябрь 2024 г.
A11: ="Следующее ТО: " & INDIRECT(ADDRESS(INT(ROUNDUP(((ROW())/6), 1)) + (2+'Исходная информация'!$N$4), 9, 1, 1, "Исходная информация")) & " " & INDIRECT(ADDRESS(INT(ROUNDUP(((ROW())/6), 1)) + (2+'Исходная информация'!$N$4), 6, 1, 1, "Исходная информация")) & " г." -> Следующее ТО: Октябрь 2025 г. | C11: ="Следующее ТО: " & INDIRECT(ADDRESS(INT(ROUNDUP(((ROW())/6), 1)) + (2+'Исходная информация'!$N$5), 9, 1, 1, "Исходная информация")) & " " & INDIRECT(ADDRESS(INT(ROUNDUP(((ROW())/6), 1)) + (2+'Исходная информация'!$N$5), 6, 1, 1, "Исходная информация")) & " г." -> Следующее ТО: Октябрь 2025 г. | E11: ="Следующее ТО: " & INDIRECT(ADDRESS(INT(ROUNDUP(((ROW())/6), 1)) + (2+'Исходная информация'!$N$4), 4, 1, 1, "Исходная информация")) & " " & INDIRECT(ADDRESS(INT(ROUNDUP(((ROW())/6), 1)) + (2+'Исходная информация'!$N$4), 6, 1, 1, "Исходная информация")) & " г." -> Следующее ТО: Октябрь 2025 г.
A12: ="Инженер ОЭиРМО: " & INDIRECT(ADDRESS(INT(ROUNDUP(((ROW())/6), 1)) + (2+'Исходная информация'!$N$4), 7, 1, 1, "Исходная информация")) -> Инженер ОЭиРМО: Игнатов А.Е. | C12: ="Инженер ОЭиРМО: " & INDIRECT(ADDRESS(INT(ROUNDUP(((ROW())/6), 1)) + (2+'Исходная информация'!$N$5), 7, 1, 1, "Исходная информация")) -> Инженер ОЭиРМО: Игнатов А.Е. | E12: ="Инженер ОЭиРМО: " & INDIRECT(ADDRESS(INT(ROUNDUP(((ROW())/6), 1)) + (2+'Исходная информация'!$N$4), 7, 1, 1, "Исходная информация")) -> Инженер ОЭиРМО: Игнатов А.Е.
A13: ="Наименование: " & INDIRECT(ADDRESS(INT(ROUNDUP(((ROW())/6), 1)) + (2+'Исходная информация'!$N$4), 1, 1, 1, "Исходная информация")) -> Наименование: Монитор глубины наркоза и седации А-2000 ХР с системой измерения биспектрального индекса (Вis ) | C13: ="Наименование: " & INDIRECT(ADDRESS(INT(ROUNDUP(((ROW())/6), 1)) + (2+'Исходная информация'!$N$4), 1, 1, 1, "Исходная информация")) -> Наименование: Монитор глубины наркоза и седации А-2000 ХР с системой измерения биспектрального индекса (Вis ) | E13: ="Наименование: " & INDIRECT(ADDRESS(INT(ROUNDUP(((ROW())/6), 1)) + (2+'Исходная информация'!$N$4), 1, 1, 1, "Исходная информация")) -> Наименование: Монитор глубины наркоза и седации А-2000 ХР с системой измерения биспектрального индекса (Вis )
A14: ="Инв. №: " & INDIRECT(ADDRESS(INT(ROUNDUP(((ROW())/6), 1)) + (2+'Исходная информация'!$N$4), 2, 1, 1, "Исходная информация")) -> Инв. №: 004410124.04.115 | C14: ="Инв. №: " & INDIRECT(ADDRESS(INT(ROUNDUP(((ROW())/6), 1)) + (2+'Исходная информация'!$N$4), 2, 1, 1, "Исходная информация")) -> Инв. №: 004410124.04.115 | E14: ="Инв. №: " & INDIRECT(ADDRESS(INT(ROUNDUP(((ROW())/6), 1)) + (2+'Исходная информация'!$N$4), 2, 1, 1, "Исходная информация")) -> Инв. №: 004410124.04.115
A15: ="Периодичность ТО: " & INDIRECT(ADDRESS(INT(ROUNDUP(((ROW())/6), 1)) + (2+'Исходная информация'!$N$4), 3, 1, 1, "Исходная информация")) -> Периодичность ТО: 1 год | C15: ="Периодичность ТО: " & INDIRECT(ADDRESS(INT(ROUNDUP(((ROW())/6), 1)) + (2+'Исходная информация'!$N$4), 3, 1, 1, "Исходная информация")) -> Периодичность ТО: 1 год | E15: ="Периодичность ТО: " & INDIRECT(ADDRESS(INT(ROUNDUP(((ROW())/6), 1)) + (2+'Исходная информация'!$N$4), 3, 1, 1, "Исходная информация")) -> Периодичность ТО: 1 год
A16: ="Проведено ТО: " & INDIRECT(ADDRESS(INT(ROUNDUP(((ROW())/6), 1)) + (2+'Исходная информация'!$N$4), 4, 1, 1, "Исходная информация")) & " " & INDIRECT(ADDRESS(INT(ROUNDUP(((ROW())/6), 1)) + (2+'Исходная информация'!$N$4), 5, 1, 1, "Исходная информация")) & " г." -> Проведено ТО: Октябрь 2024 г. | C16: ="Проведено ТО: " & INDIRECT(ADDRESS(INT(ROUNDUP(((ROW())/6), 1)) + (2+'Исходная информация'!$N$4), 4, 1, 1, "Исходная информация")) & " " & INDIRECT(ADDRESS(INT(ROUNDUP(((ROW())/6), 1)) + (2+'Исходная информация'!$N$4), 5, 1, 1, "Исходная информация")) & " г." -> Проведено ТО: Октябрь 2024 г. | E16: ="Проведено ТО: " & INDIRECT(ADDRESS(INT(ROUNDUP(((ROW())/6), 1)) + (2+'Исходная информация'!$N$4), 4, 1, 1, "Исходная информация")) & " " & INDIRECT(ADDRESS(INT(ROUNDUP(((ROW())/6), 1)) + (2+'Исходная информация'!$N$4), 5, 1, 1, "Исходная информация")) & " г." -> Проведено ТО: Октябрь 2024 г.
A17: ="Следующее ТО: " & INDIRECT(ADDRESS(INT(ROUNDUP(((ROW())/6), 1)) + (2+'Исходная информация'!$N$4), 9, 1, 1, "Исходная информация")) & " " & INDIRECT(ADDRESS(INT(ROUNDUP(((ROW())/6), 1)) + (2+'Исходная информация'!$N$4), 6, 1, 1, "Исходная информация")) & " г." -> Следующее ТО: Октябрь 2025 г. | C17: ="Следующее ТО: " & INDIRECT(ADDRESS(INT(ROUNDUP(((ROW())/6), 1)) + (2+'Исходная информация'!$N$4), 9, 1, 1, "Исходная информация")) & " " & INDIRECT(ADDRESS(INT(ROUNDUP(((ROW())/6), 1)) + (2+'Исходная информация'!$N$4), 6, 1, 1, "Исходная информация")) & " г." -> Следующее ТО: Октябрь 2025 г. | E17: ="Следующее ТО: " & INDIRECT(ADDRESS(INT(ROUNDUP(((ROW())/6), 1)) + (2+'Исходная информация'!$N$4), 4, 1, 1, "Исходная информация")) & " " & INDIRECT(ADDRESS(INT(ROUNDUP(((ROW())/6), 1)) + (2+'Исходная информация'!$N$4), 6, 1, 1, "Исходная информация")) & " г." -> Следующее ТО: Октябрь 2025 г.
A18: ="Инженер ОЭиРМО: " & INDIRECT(ADDRESS(INT(ROUNDUP(((ROW())/6), 1)) + (2+'Исходная информация'!$N$4), 7, 1, 1, "Исходная информация")) -> Инженер ОЭиРМО: Игнатов А.Е. | C18: ="Инженер ОЭиРМО: " & INDIRECT(ADDRESS(INT(ROUNDUP(((ROW())/6), 1)) + (2+'Исходная информация'!$N$4), 7, 1, 1, "Исходная информация")) -> Инженер ОЭиРМО: Игнатов А.Е. | E18: ="Инженер ОЭиРМО: " & INDIRECT(ADDRESS(INT(ROUNDUP(((ROW())/6), 1)) + (2+'Исходная информация'!$N$4), 7, 1, 1, "Исходная информация")) -> Инженер ОЭиРМО: Игнатов А.Е.
A19: ="Наименование: " & INDIRECT(ADDRESS(INT(ROUNDUP(((ROW())/6), 1)) + (2+'Исходная информация'!$N$4), 1, 1, 1, "Исходная информация")) -> Наименование: Монитор глубины наркоза и седации А-2000 ХР с системой измерения биспектрального индекса (Вis ) | C19: ="Наименование: " & INDIRECT(ADDRESS(INT(ROUNDUP(((ROW())/6), 1)) + (2+'Исходная информация'!$N$4), 1, 1, 1, "Исходная информация")) -> Наименование: Монитор глубины наркоза и седации А-2000 ХР с системой измерения биспектрального индекса (Вis ) | E19: ="Наименование: " & INDIRECT(ADDRESS(INT(ROUNDUP(((ROW())/6), 1)) + (2+'Исходная информация'!$N$4), 1, 1, 1, "Исходная информация")) -> Наименование: Монитор глубины наркоза и седации А-2000 ХР с системой измерения биспектрального индекса (Вis )
A20: ="Инв. №: " & INDIRECT(ADDRESS(INT(ROUNDUP(((ROW())/6), 1)) + (2+'Исходная информация'!$N$4), 2, 1, 1, "Исходная информация")) -> Инв. №: 004410124.04.116 | C20: ="Инв. №: " & INDIRECT(ADDRESS(INT(ROUNDUP(((ROW())/6), 1)) + (2+'Исходная информация'!$N$4), 2, 1, 1, "Исходная информация")) -> Инв. №: 004410124.04.116 | E20: ="Инв. №: " & INDIRECT(ADDRESS(INT(ROUNDUP(((ROW())/6), 1)) + (2+'Исходная информация'!$N$4), 2, 1, 1, "Исходная информация")) -> Инв. №: 004410124.04.116
A21: ="Периодичность ТО: " & INDIRECT(ADDRESS(INT(ROUNDUP(((ROW())/6), 1)) + (2+'Исходная информация'!$N$4), 3, 1, 1, "Исходная информация")) -> Периодичность ТО: 1 год | C21: ="Периодичность ТО: " & INDIRECT(ADDRESS(INT(ROUNDUP(((ROW())/6), 1)) + (2+'Исходная информация'!$N$4), 3, 1, 1, "Исходная информация")) -> Периодичность ТО: 1 год | E21: ="Периодичность ТО: " & INDIRECT(ADDRESS(INT(ROUNDUP(((ROW())/6), 1)) + (2+'Исходная информация'!$N$4), 3, 1, 1, "Исходная информация")) -> Периодичность ТО: 1 год
A22: ="Проведено ТО: " & INDIRECT(ADDRESS(INT(ROUNDUP(((ROW())/6), 1)) + (2+'Исходная информация'!$N$4), 4, 1, 1, "Исходная информация")) & " " & INDIRECT(ADDRESS(INT(ROUNDUP(((ROW())/6), 1)) + (2+'Исходная информация'!$N$4), 5, 1, 1, "Исходная информация")) & " г." -> Проведено ТО: Октябрь 2024 г. | C22: ="Проведено ТО: " & INDIRECT(ADDRESS(INT(ROUNDUP(((ROW())/6), 1)) + (2+'Исходная информация'!$N$4), 4, 1, 1, "Исходная информация")) & " " & INDIRECT(ADDRESS(INT(ROUNDUP(((ROW())/6), 1)) + (2+'Исходная информация'!$N$4), 5, 1, 1, "Исходная информация")) & " г." -> Проведено ТО: Октябрь 2024 г. | E22: ="Проведено ТО: " & INDIRECT(ADDRESS(INT(ROUNDUP(((ROW())/6), 1)) + (2+'Исходная информация'!$N$4), 4, 1, 1, "Исходная информация")) & " " & INDIRECT(ADDRESS(INT(ROUNDUP(((ROW())/6), 1)) + (2+'Исходная информация'!$N$4), 5, 1, 1, "Исходная информация")) & " г." -> Проведено ТО: Октябрь 2024 г.
A23: ="Следующее ТО: " & INDIRECT(ADDRESS(INT(ROUNDUP(((ROW())/6), 1)) + (2+'Исходная информация'!$N$4), 9, 1, 1, "Исходная информация")) & " " & INDIRECT(ADDRESS(INT(ROUNDUP(((ROW())/6), 1)) + (2+'Исходная информация'!$N$4), 6, 1, 1, "Исходная информация")) & " г." -> Следующее ТО: Октябрь 2025 г. | C23: ="Следующее ТО: " & INDIRECT(ADDRESS(INT(ROUNDUP(((ROW())/6), 1)) + (2+'Исходная информация'!$N$4), 9, 1, 1, "Исходная информация")) & " " & INDIRECT(ADDRESS(INT(ROUNDUP(((ROW())/6), 1)) + (2+'Исходная информация'!$N$4), 6, 1, 1, "Исходная информация")) & " г." -> Следующее ТО: Октябрь 2025 г. | E23: ="Следующее ТО: " & INDIRECT(ADDRESS(INT(ROUNDUP(((ROW())/6), 1)) + (2+'Исходная информация'!$N$4), 4, 1, 1, "Исходная информация")) & " " & INDIRECT(ADDRESS(INT(ROUNDUP(((ROW())/6), 1)) + (2+'Исходная информация'!$N$4), 6, 1, 1, "Исходная информация")) & " г." -> Следующее ТО: Октябрь 2025 г.
A24: ="Инженер ОЭиРМО: " & INDIRECT(ADDRESS(INT(ROUNDUP(((ROW())/6), 1)) + (2+'Исходная информация'!$N$4), 7, 1, 1, "Исходная информация")) -> Инженер ОЭиРМО: Игнатов А.Е. | C24: ="Инженер ОЭиРМО: " & INDIRECT(ADDRESS(INT(ROUNDUP(((ROW())/6), 1)) + (2+'Исходная информация'!$N$4), 7, 1, 1, "Исходная информация")) -> Инженер ОЭиРМО: Игнатов А.Е. | E24: ="Инженер ОЭиРМО: " & INDIRECT(ADDRESS(INT(ROUNDUP(((ROW())/6), 1)) + (2+'Исходная информация'!$N$4), 7, 1, 1, "Исходная информация")) -> Инженер ОЭиРМО: Игнатов А.Е.
A25: ="Наименование: " & INDIRECT(ADDRESS(INT(ROUNDUP(((ROW())/6), 1)) + (2+'Исходная информация'!$N$4), 1, 1, 1, "Исходная информация")) -> Наименование: Монитор глубины наркоза и седации А-2000 ХР с системой измерения биспектрального индекса (Вis ) | C25: ="Наименование: " & INDIRECT(ADDRESS(INT(ROUNDUP(((ROW())/6), 1)) + (2+'Исходная информация'!$N$4), 1, 1, 1, "Исходная информация")) -> Наименование: Монитор глубины наркоза и седации А-2000 ХР с системой измерения биспектрального индекса (Вis ) | E25: ="Наименование: " & INDIRECT(ADDRESS(INT(ROUNDUP(((ROW())/6), 1)) + (2+'Исходная информация'!$N$4), 1, 1, 1, "Исходная информация")) -> Наименование: Монитор глубины наркоза и седации А-2000 ХР с системой измерения биспектрального индекса (Вis )
A26: ="Инв. №: " & INDIRECT(ADDRESS(INT(ROUNDUP(((ROW())/6), 1)) + (2+'Исходная информация'!$N$4), 2, 1, 1, "Исходная информация")) -> Инв. №: 004410124.04.117 | C26: ="Инв. №: " & INDIRECT(ADDRESS(INT(ROUNDUP(((ROW())/6), 1)) + (2+'Исходная информация'!$N$4), 2, 1, 1, "Исходная информация")) -> Инв. №: 004410124.04.117 | E26: ="Инв. №: " & INDIRECT(ADDRESS(INT(ROUNDUP(((ROW())/6), 1)) + (2+'Исходная информация'!$N$4), 2, 1, 1, "Исходная информация")) -> Инв. №: 004410124.04.117
A27: ="Периодичность ТО: " & INDIRECT(ADDRESS(INT(ROUNDUP(((ROW())/6), 1)) + (2+'Исходная информация'!$N$4), 3, 1, 1, "Исходная информация")) -> Периодичность ТО: 1 год | C27: ="Периодичность ТО: " & INDIRECT(ADDRESS(INT(ROUNDUP(((ROW())/6), 1)) + (2+'Исходная информация'!$N$4), 3, 1, 1, "Исходная информация")) -> Периодичность ТО: 1 год | E27: ="Периодичность ТО: " & INDIRECT(ADDRESS(INT(ROUNDUP(((ROW())/6), 1)) + (2+'Исходная информация'!$N$4), 3, 1, 1, "Исходная информация")) -> Периодичность ТО: 1 год
A28: ="Проведено ТО: " & INDIRECT(ADDRESS(INT(ROUNDUP(((ROW())/6), 1)) + (2+'Исходная информация'!$N$4), 4, 1, 1, "Исходная информация")) & " " & INDIRECT(ADDRESS(INT(ROUNDUP(((ROW())/6), 1)) + (2+'Исходная информация'!$N$4), 5, 1, 1, "Исходная информация")) & " г." -> Проведено ТО: Октябрь 2024 г. | C28: ="Проведено ТО: " & INDIRECT(ADDRESS(INT(ROUNDUP(((ROW())/6), 1)) + (2+'Исходная информация'!$N$4), 4, 1, 1, "Исходная информация")) & " " & INDIRECT(ADDRESS(INT(ROUNDUP(((ROW())/6), 1)) + (2+'Исходная информация'!$N$4), 5, 1, 1, "Исходная информация")) & " г." -> Проведено ТО: Октябрь 2024 г. | E28: ="Проведено ТО: " & INDIRECT(ADDRESS(INT(ROUNDUP(((ROW())/6), 1)) + (2+'Исходная информация'!$N$4), 4, 1, 1, "Исходная информация")) & " " & INDIRECT(ADDRESS(INT(ROUNDUP(((ROW())/6), 1)) + (2+'Исходная информация'!$N$4), 5, 1, 1, "Исходная информация")) & " г." -> Проведено ТО: Октябрь 2024 г.
A29: ="Следующее ТО: " & INDIRECT(ADDRESS(INT(ROUNDUP(((ROW())/6), 1)) + (2+'Исходная информация'!$N$4), 9, 1, 1, "Исходная информация")) & " " & INDIRECT(ADDRESS(INT(ROUNDUP(((ROW())/6), 1)) + (2+'Исходная информация'!$N$4), 6, 1, 1, "Исходная информация")) & " г." -> Следующее ТО: Октябрь 2025 г. | C29: ="Следующее ТО: " & INDIRECT(ADDRESS(INT(ROUNDUP(((ROW())/6), 1)) + (2+'Исходная информация'!$N$4), 9, 1, 1, "Исходная информация")) & " " & INDIRECT(ADDRESS(INT(ROUNDUP(((ROW())/6), 1)) + (2+'Исходная информация'!$N$4), 6, 1, 1, "Исходная информация")) & " г." -> Следующее ТО: Октябрь 2025 г. | E29: ="Следующее ТО: " & INDIRECT(ADDRESS(INT(ROUNDUP(((ROW())/6), 1)) + (2+'Исходная информация'!$N$4), 4, 1, 1, "Исходная информация")) & " " & INDIRECT(ADDRESS(INT(ROUNDUP(((ROW())/6), 1)) + (2+'Исходная информация'!$N$4), 6, 1, 1, "Исходная информация")) & " г." -> Следующее ТО: Октябрь 2025 г.
A30: ="Инженер ОЭиРМО: " & INDIRECT(ADDRESS(INT(ROUNDUP(((ROW())/6), 1)) + (2+'Исходная информация'!$N$4), 7, 1, 1, "Исходная информация")) -> Инженер ОЭиРМО: Игнатов А.Е. | C30: ="Инженер ОЭиРМО: " & INDIRECT(ADDRESS(INT(ROUNDUP(((ROW())/6), 1)) + (2+'Исходная информация'!$N$4), 7, 1, 1, "Исходная информация")) -> Инженер ОЭиРМО: Игнатов А.Е. | E30: ="Инженер ОЭиРМО: " & INDIRECT(ADDRESS(INT(ROUNDUP(((ROW())/6), 1)) + (2+'Исходная информация'!$N$4), 7, 1, 1, "Исходная информация")) -> Инженер ОЭиРМО: Игнатов А.Е.
A31: ="Наименование: " & INDIRECT(ADDRESS(INT(ROUNDUP(((ROW())/6), 1)) + (2+'Исходная информация'!$N$4), 1, 1, 1, "Исходная информация")) -> Наименование: Монитор глубины наркоза и седации А-2000 ХР с системой измерения биспектрального индекса (Вis ) | C31: ="Наименование: " & INDIRECT(ADDRESS(INT(ROUNDUP(((ROW())/6), 1)) + (2+'Исходная информация'!$N$4), 1, 1, 1, "Исходная информация")) -> Наименование: Монитор глубины наркоза и седации А-2000 ХР с системой измерения биспектрального индекса (Вis ) | E31: ="Наименование: " & INDIRECT(ADDRESS(INT(ROUNDUP(((ROW())/6), 1)) + (2+'Исходная информация'!$N$4), 1, 1, 1, "Исходная информация")) -> Наименование: Монитор глубины наркоза и седации А-2000 ХР с системой измерения биспектрального индекса (Вis )
A32: ="Инв. №: " & INDIRECT(ADDRESS(INT(ROUNDUP(((ROW())/6), 1)) + (2+'Исходная информация'!$N$4), 2, 1, 1, "Исходная информация")) -> Инв. №: 004410124.04.118 | C32: ="Инв. №: " & INDIRECT(ADDRESS(INT(ROUNDUP(((ROW())/6), 1)) + (2+'Исходная информация'!$N$4), 2, 1, 1, "Исходная информация")) -> Инв. №: 004410124.04.118 | E32: ="Инв. №: " & INDIRECT(ADDRESS(INT(ROUNDUP(((ROW())/6), 1)) + (2+'Исходная информация'!$N$4), 2, 1, 1, "Исходная информация")) -> Инв. №: 004410124.04.118
A33: ="Периодичность ТО: " & INDIRECT(ADDRESS(INT(ROUNDUP(((ROW())/6), 1)) + (2+'Исходная информация'!$N$4), 3, 1, 1, "Исходная информация")) -> Периодичность ТО: 1 год | C33: ="Периодичность ТО: " & INDIRECT(ADDRESS(INT(ROUNDUP(((ROW())/6), 1)) + (2+'Исходная информация'!$N$4), 3, 1, 1, "Исходная информация")) -> Периодичность ТО: 1 год | E33: ="Периодичность ТО: " & INDIRECT(ADDRESS(INT(ROUNDUP(((ROW())/6), 1)) + (2+'Исходная информация'!$N$4), 3, 1, 1, "Исходная информация")) -> Периодичность ТО: 1 год
A34: ="Проведено ТО: " & INDIRECT(ADDRESS(INT(ROUNDUP(((ROW())/6), 1)) + (2+'Исходная информация'!$N$4), 4, 1, 1, "Исходная информация")) & " " & INDIRECT(ADDRESS(INT(ROUNDUP(((ROW())/6), 1)) + (2+'Исходная информация'!$N$4), 5, 1, 1, "Исходная информация")) & " г." -> Проведено ТО: Октябрь 2024 г. | C34: ="Проведено ТО: " & INDIRECT(ADDRESS(INT(ROUNDUP(((ROW())/6), 1)) + (2+'Исходная информация'!$N$4), 4, 1, 1, "Исходная информация")) & " " & INDIRECT(ADDRESS(INT(ROUNDUP(((ROW())/6), 1)) + (2+'Исходная информация'!$N$4), 5, 1, 1, "Исходная информация")) & " г." -> Проведено ТО: Октябрь 2024 г. | E34: ="Проведено ТО: " & INDIRECT(ADDRESS(INT(ROUNDUP(((ROW())/6), 1)) + (2+'Исходная информация'!$N$4), 4, 1, 1, "Исходная информация")) & " " & INDIRECT(ADDRESS(INT(ROUNDUP(((ROW())/6), 1)) + (2+'Исходная информация'!$N$4), 5, 1, 1, "Исходная информация")) & " г." -> Проведено ТО: Октябрь 2024 г.
A35: ="Следующее ТО: " & INDIRECT(ADDRESS(INT(ROUNDUP(((ROW())/6), 1)) + (2+'Исходная информация'!$N$4), 9, 1, 1, "Исходная информация")) & " " & INDIRECT(ADDRESS(INT(ROUNDUP(((ROW())/6), 1)) + (2+'Исходная информация'!$N$4), 6, 1, 1, "Исходная информация")) & " г." -> Следующее ТО: Октябрь 2025 г. | C35: ="Следующее ТО: " & INDIRECT(ADDRESS(INT(ROUNDUP(((ROW())/6), 1)) + (2+'Исходная информация'!$N$4), 9, 1, 1, "Исходная информация")) & " " & INDIRECT(ADDRESS(INT(ROUNDUP(((ROW())/6), 1)) + (2+'Исходная информация'!$N$4), 6, 1, 1, "Исходная информация")) & " г." -> Следующее ТО: Октябрь 2025 г. | E35: ="Следующее ТО: " & INDIRECT(ADDRESS(INT(ROUNDUP(((ROW())/6), 1)) + (2+'Исходная информация'!$N$4), 4, 1, 1, "Исходная информация")) & " " & INDIRECT(ADDRESS(INT(ROUNDUP(((ROW())/6), 1)) + (2+'Исходная информация'!$N$4), 6, 1, 1, "Исходная информация")) & " г." -> Следующее ТО: Октябрь 2025 г.
A36: ="Инженер ОЭиРМО: " & INDIRECT(ADDRESS(INT(ROUNDUP(((ROW())/6), 1)) + (2+'Исходная информация'!$N$4), 7, 1, 1, "Исходная информация")) -> Инженер ОЭиРМО: Игнатов А.Е. | C36: ="Инженер ОЭиРМО: " & INDIRECT(ADDRESS(INT(ROUNDUP(((ROW())/6), 1)) + (2+'Исходная информация'!$N$4), 7, 1, 1, "Исходная информация")) -> Инженер ОЭиРМО: Игнатов А.Е. | E36: ="Инженер ОЭиРМО: " & INDIRECT(ADDRESS(INT(ROUNDUP(((ROW())/6), 1)) + (2+'Исходная информация'!$N$4), 7, 1, 1, "Исходная информация")) -> Инженер ОЭиРМО: Игнатов А.Е.
A37: ="Наименование: " & INDIRECT(ADDRESS(INT(ROUNDUP(((ROW())/6), 1)) + (2+'Исходная информация'!$N$4), 1, 1, 1, "Исходная информация")) -> Наименование: Монитор глубины наркоза и седации А-2000 ХР с системой измерения биспектрального индекса (Вis ) | C37: ="Наименование: " & INDIRECT(ADDRESS(INT(ROUNDUP(((ROW())/6), 1)) + (2+'Исходная информация'!$N$4), 1, 1, 1, "Исходная информация")) -> Наименование: Монитор глубины наркоза и седации А-2000 ХР с системой измерения биспектрального индекса (Вis ) | E37: ="Наименование: " & INDIRECT(ADDRESS(INT(ROUNDUP(((ROW())/6), 1)) + (2+'Исходная информация'!$N$4), 1, 1, 1, "Исходная информация")) -> Наименование: Монитор глубины наркоза и седации А-2000 ХР с системой измерения биспектрального индекса (Вis )
A38: ="Инв. №: " & INDIRECT(ADDRESS(INT(ROUNDUP(((ROW())/6), 1)) + (2+'Исходная информация'!$N$4), 2, 1, 1, "Исходная информация")) -> Инв. №: 004410124.04.119 | C38: ="Инв. №: " & INDIRECT(ADDRESS(INT(ROUNDUP(((ROW())/6), 1)) + (2+'Исходная информация'!$N$4), 2, 1, 1, "Исходная информация")) -> Инв. №: 004410124.04.119 | E38: ="Инв. №: " & INDIRECT(ADDRESS(INT(ROUNDUP(((ROW())/6), 1)) + (2+'Исходная информация'!$N$4), 2, 1, 1, "Исходная информация")) -> Инв. №: 004410124.04.119
A39: ="Периодичность ТО: " & INDIRECT(ADDRESS(INT(ROUNDUP(((ROW())/6), 1)) + (2+'Исходная информация'!$N$4), 3, 1, 1, "Исходная информация")) -> Периодичность ТО: 1 год | C39: ="Периодичность ТО: " & INDIRECT(ADDRESS(INT(ROUNDUP(((ROW())/6), 1)) + (2+'Исходная информация'!$N$4), 3, 1, 1, "Исходная информация")) -> Периодичность ТО: 1 год | E39: ="Периодичность ТО: " & INDIRECT(ADDRESS(INT(ROUNDUP(((ROW())/6), 1)) + (2+'Исходная информация'!$N$4), 3, 1, 1, "Исходная информация")) -> Периодичность ТО: 1 год
A40: ="Проведено ТО: " & INDIRECT(ADDRESS(INT(ROUNDUP(((ROW())/6), 1)) + (2+'Исходная информация'!$N$4), 4, 1, 1, "Исходная информация")) & " " & INDIRECT(ADDRESS(INT(ROUNDUP(((ROW())/6), 1)) + (2+'Исходная информация'!$N$4), 5, 1, 1, "Исходная информация")) & " г." -> Проведено ТО: Октябрь 2024 г. | C40: ="Проведено ТО: " & INDIRECT(ADDRESS(INT(ROUNDUP(((ROW())/6), 1)) + (2+'Исходная информация'!$N$4), 4, 1, 1, "Исходная информация")) & " " & INDIRECT(ADDRESS(INT(ROUNDUP(((ROW())/6), 1)) + (2+'Исходная информация'!$N$4), 5, 1, 1, "Исходная информация")) & " г." -> Проведено ТО: Октябрь 2024 г. | E40: ="Проведено ТО: " & INDIRECT(ADDRESS(INT(ROUNDUP(((ROW())/6), 1)) + (2+'Исходная информация'!$N$4), 4, 1, 1, "Исходная информация")) & " " & INDIRECT(ADDRESS(INT(ROUNDUP(((ROW())/6), 1)) + (2+'Исходная информация'!$N$4), 5, 1, 1, "Исходная информация")) & " г." -> Проведено ТО: Октябрь 2024 г.
...
